Workbook
Name Results: 'simulatie data'!#REF!
Name Results_1: 'simulatie data'!$A$1:$EZ$1002

Sheet simulatie data
A1: minutes | B1: plate | C1: mouth | D1: corpus | E1: antrum | F1: duodenum 1 | G1: duodenum 2 | H1: jejunum 1 | I1: jejunum 2 | J1: jejunum 3 | K1: ileum 1 | L1: ileum 2 | M1: ileum 3 | N1: ileum 4 | O1: ileum 5 | P1: ileum 6 | Q1: colon | R1: enterocytes/100 | S1: total volume SI | T1: CCK | U1: PYY | V1: gastric emptying | W1: calories proximal | X1: calories distal | Y1: calories colon | Z1: calories absorbed | AA1: gastric tone | AB1: fullness | AC1: hunger | AD1: peptides upper gastric | AE1: peptides antrum | AF1: peptides duodenum 1 | AG1: peptides duodenum 2 | AH1: peptides jejunum 1 | AI1: peptides jejunum 2 | AJ1: peptides jejunum 3 | AK1: peptides ileum 1 | AL1: peptides ileum 2 | AM1: peptides ileum 3 | AN1: peptides ileum 4 | AO1: peptides ileum 5 | AP1: peptides ileum 6 | AQ1: peptides colon | AR1: GIP | AS1: GLP1 | AT1: glucose upper gastric | AU1: glucose antrum | AV1: glucose duodenum 1 | AW1: glucose duodenum 2 | AX1: glucose jejunum 1 | AY1: glucose jejunum 2 | AZ1: glucose jejunum 3 | BA1: glucose ileum 1 | BB1: glucose ileum 2 | BC1: glucose ileum 3 | BD1: glucose ileum 4 | BE1: glucose ileum 5 | BF1: glucose ileum 6 | BG1: glucose colon | BH1: fat delivered to colon | BI1: casein delivered to colon | BJ1: glucose delivered to colon | BK1: glucose absorbed | BL1: fatty acids absorbed | BM1: conjugated bile absorbed | BN1: fatty acid bile micelles absorbed | BO1: casein small peptides absorbed | BP1: small peptides absorbed | BQ1: pH plate | BR1: pH mouth | BS1: pH upper gastric | BT1: pH antrum | BU1: pH duodenum 1 | BV1: pH duodenum 2 | BW1: pH jejunum 1 | BX1: pH jejunum 2 | BY1: pH jejunum 3 | BZ1: pH ileum 1 | CA1: pH ileum 2 | CB1: pH ileum 3 | CC1: pH ileum 4 | CD1: pH ileum 5 | CE1: pH ileum 6 | CF1: pH colon | CG1: Units pepsin in corpus | CH1: Units pepsin in antrum | CI1: solids_in_corpus | CJ1: solids_in_fundus | CK1: solids_in_antrum | CL1: total solids in stomach | CM1: serum glucose (mMol/l) | CN1: serum insulin (pMol/l) | CO1: pharmaceutical absorbed (g) | CP1: bloodserumconc pharmaceutical (mg/l) | CQ1: CCK emptying stress | CR1: Osmotic emptying stress | CS1: pH emptying stress | CT1: pH fundus | CU1: fundus | CV1: starch fundus | CW1: starch colon | CX1: sucrase_inhibitie[7] | CY1: absorption_rate[7-3] | CZ1: absorption_rate[7-1] | DA1: glucose in brush[7] | DB1: arabinose in brush[7] | DC1: sucrose in brush[7] | DD1: sucrase_inhibitie[15] | DE1: absorption_rate[15-3] | DF1: absorption_rate[15-1] | DG1: osmotic_value_brush_proximal | DH1: osmotic_value_brush_distal | DI1: osmotic_value_lumen_duodenum | DJ1: osmotic_value_lumen_distal | DK1: serum_glucose_mg_dl | DL1: serum_insulin_mU_l | DM1: GLP1gastricemptying_stress | DN1: Viscousgastricemptying_stress | DO1: 13C serum_glucose (mMol/l) | DP1: 2H serum_glucose (mMol/l) | DQ1: glucose RaE (Mol/min) | DR1: up[4] | DS1: intercellulaire glucose muscle adipose (mMol/l) | DT1: intercellulaire glucose skin (mMol/l) | DU1: total_glucose_absorption_rate (Mol/min) | DV1: Gastric Volume (mL) | DW1: HbA1C (%) | DX1: Leucine absorbed (g) | DY1: total SI water absorption rate (g/min) | DZ1: MCC status | EA1: Ghrelin | EB1: Motilin | EC1: bile_secretion_rate (g/min) | ED1: Pancreatic fluid secretion (g/min) | EE1: gastric fluid secretion (g/min) | EF1: saliva secretion (g/ml) | EG1: secreted gastric fluid (g) | EH1: secreted conjugated bile salt (g) | EI1: secreted panceratic fluid (g) | EJ1: secreted_saliva (g) | EK1: gall bladder volume (g) | EL1: conjugated bile salt concentration in gall bladder (g/g) | EM1: duodenal conjugated bile salt concentration (g/g) | EN1: gal bladder emptying rate (g/min) | EO1: secteted bile (g) | EP1: blood bile salt pool (g) | EQ1: unconjugated bile salt in colon (g) | ER1: conjugated bile salt in secreted_bile (g/g) | ES1: secretin (a.u.) | ET1: glucagon (a.u.) | EU1: glycogen (g) | EV1: RC13/C12 | EW1: total lingual lipase lipolysis rate (%/min) | EX1: total gastric lipase lipolysis rate (%/min) | EY1: total pancreatic lipase lipolysis rate (%/min)
A2: 1 | B2: 0 | C2: 0.90611669 | D2: 14.008136 | E2: 1.0439496 | F2: 12.085287 | G2: 18.492255 | H2: 23.930616 | I2: 23.187037 | J2: 22.462849 | K2: 21.759321 | L2: 21.074494 | M2: 20.411203 | N2: 19.773553 | O2: 19.169186 | P2: 18.610217 | Q2: 862.45102 | R2: 0 | S2: 220.95602 | T2: 0 | U2: 0.00113 | V2: 0 | W2: 6e-05 | X2: 0.00035 | Y2: 1.5222 | Z2: 6e-05 | AA2: 3.34285 | AB2: 0.89523 | AC2: 7.91899 | AD2: 0 | AE2: 0 | AF2: 0 | AG2: 0 | AH2: 0 | AI2: 0 | AJ2: 0 | AK2: 0 | AL2: 0 | AM2: 0 | AN2: 0 | AO2: 0 | AP2: 0 | AQ2: 0.07448 | AR2: 4e-05 | AS2: 0.00046 | AT2: 0 | AU2: 0 | AV2: 0 | AW2: 0 | AX2: 0 | AY2: 0 | AZ2: 0 | BA2: 0 | BB2: 0 | BC2: 0 | BD2: 0 | BE2: 0 | BF2: 0 | BG2: 0.0022 | BH2: 0.07216 | BI2: 0 | BJ2: 0.0022 | BK2: 0 | BL2: 0 | BM2: 5e-05 | BN2: 0 | BO2: 0 | BP2: 0 | BQ2: 7 | BR2: 6.2748975 | BS2: 2.2978271 | BT2: 2.5265967 | BU2: 4.814292 | BV2: 6.0021338 | BW2: 6.8468213 | BX2: 7.6475146 | BY2: 8.1138525 | BZ2: 8.3074268 | CA2: 8.4658057 | CB2: 8.6065869 | CC2: 8.7297705 | CD2: 8.8353565 | CE2: 8.9145459 | CF2: 0 | CG2: 2294.4754 | CH2: 2702.3972 | CI2: 0.12435 | CJ2: 0.00439 | CK2: 0.00275 | CL2: 0.13149 | CM2: 3.93348 | CN2: 70.26577 | CO2: 0 | CP2: 0 | CQ2: 0 | CR2: 0 | CS2: 0.17855 | CT2: 1.83149 | CU2: 6.70818 | CV2: 0 | CW2: 0 | CX2: 1 | CY2: 0 | CZ2: 0.07725 | DA2: 0 | DB2: 0 | DC2: 0 | DD2: 1 | DE2: 0 | DF2: 0.06277 | DG2: 0 | DH2: 0 | DI2: 0 | DJ2: 0 | DK2: 70.86391 | DL2: 10.5346 | DM2: 0.0065 | DN2: 0.31498 | DO2: 0 | DP2: 0.02329 | DQ2: 0 | DR2: 0 | DS2: 3.08123 | DT2: 3.93343 | DU2: 0 | DV2: 19.36986 | DW2: 0.0025534795 | DX2: 0 | DY2: 0.73359 | DZ2: 1 | EA2: 132.36855 | EB2: 87.45072 | EC2: 0.13468 | ED2: 0 | EE2: 0.45723 | EF2: 0.19051 | EG2: 0.4391 | EH2: 0.00117 | EI2: 0.02116 | EJ2: 2.84835 | EK2: 15.81842 | EL2: 0.01375 | EM2: 0.00116 | EN2: 0.03978 | EO2: 82.75736 | EP2: 0.00734 | EQ2: 0.20554 | ER2: 0.00851 | ES2: 2.71231 | ET2: 8.81088 | EU2: 100 | EV2: 1e-05 | EW2: 0 | EX2: 0 | EY2: 0.81904
A3: 2 | B3: 0 | C3: 12.305328 | D3: 5.0737758 | E3: 2.287444 | F3: 13.351062 | G3: 18.608347 | H3: 23.934937 | I3: 23.186379 | J3: 22.462007 | K3: 21.758375 | L3: 21.073417 | M3: 20.409826 | N3: 19.771503 | O3: 19.16578 | P3: 18.60438 | Q3: 863.77832 | R3: 0 | S3: 222.32601 | T3: 5e-05 | U3: 0.00126 | V3: 0.22194 | W3: 0.08625 | X3: 0.00035 | Y3: 1.52221 | Z3: 0.00191 | AA3: 3.50923 | AB3: 1.00615 | AC3: 7.89665 | AD3: 0.01151 | AE3: 0.00394 | AF3: 0.00243 | AG3: 7e-05 | AH3: 0 | AI3: 0 | AJ3: 0 | AK3: 0 | AL3: 0 | AM3: 0 | AN3: 0 | AO3: 0 | AP3: 0 | AQ3: 0.07448 | AR3: 0.00111 | AS3: 0.00045 | AT3: 0 | AU3: 0 | AV3: 0.00642 | AW3: 0.00034 | AX3: 1e-05 | AY3: 0 | AZ3: 0 | BA3: 0 | BB3: 0 | BC3: 0 | BD3: 0 | BE3: 0 | BF3: 0 | BG3: 0.0022 | BH3: 0.07217 | BI3: 0 | BJ3: 0.0022 | BK3: 0.00027 | BL3: 0 | BM3: 5e-05 | BN3: 0 | BO3: 0 | BP3: 1e-05 | BQ3: 7 | BR3: 4.9198779 | BS3: 3.6528467 | BT3: 2.6233838 | BU3: 5.3334228 | BV3: 6.0021338 | BW3: 6.8380225 | BX3: 7.6475146 | BY3: 8.1138525 | BZ3: 8.3074268 | CA3: 8.4658057 | CB3: 8.6065869 | CC3: 8.7297705 | CD3: 8.8353565 | CE3: 8.9145459 | CF3: 0 | CG3: 1670.1412 | CH3: 1937.6525 | CI3: 0.28664 | CJ3: 0.64906 | CK3: 0.1663 | CL3: 1.102 | CM3: 3.93349 | CN3: 70.26614 | CO3: 0 | CP3: 0 | CQ3: 0.00057 | CR3: 0.04089 | CS3: 0.1111 | CT3: 2.77296 | CU3: 22.70636 | CV3: 0.54646 | CW3: 0 | CX3: 1 | CY3: 0 | CZ3: 0.07726 | DA3: 0 | DB3: 0 | DC3: 0 | DD3: 1 | DE3: 0 | DF3: 0.06275 | DG3: 0.00041 | DH3: 0 | DI3: 0.00075 | DJ3: 0 | DK3: 70.86417 | DL3: 10.53465 | DM3: 0.00629 | DN3: 0.30088 | DO3: 0 | DP3: 0.02329 | DQ3: 0 | DR3: 13.36251 | DS3: 3.08124 | DT3: 3.93344 | DU3: 2e-05 | DV3: 28.76985 | DW3: 0.0025583085 | DX3: 0 | DY3: 0.74838 | DZ3: 1 | EA3: 132.36165 | EB3: 87.47061 | EC3: 0.13469 | ED3: 0 | EE3: 1.71472 | EF3: 0.4243 | EG3: 1.47893 | EH3: 0.0023 | EI3: 0.04234 | EJ3: 9.07351 | EK3: 15.8266 | EL3: 0.01379 | EM3: 0.00116 | EN3: 0.03974 | EO3: 82.89191 | EP3: 0.0069 | EQ3: 0.20542 | ER3: 0.00831 | ES3: 2.7143 | ET3: 8.81084 | EU3: 100 | EV3: 0.02216 | EW3: 0.37543 | EX3: 0 | EY3: 0.88035
A4: 3 | B4: 0 | C4: 13.138338 | D4: 12.842655 | E4: 4.0528276 | F4: 14.666184 | G4: 18.94315 | H4: 23.959624 | I4: 23.186813 | J4: 22.461213 | K4: 21.75768 | L4: 21.07235 | M4: 20.408469 | N4: 19.769505 | O4: 19.162487 | P4: 18.598751 | Q4: 865.10493 | R4: 0 | S4: 223.98623 | T4: 0.00263 | U4: 0.01478 | V4: 1.05936 | W4: 1.61199 | X4: 0.00035 | Y4: 1.52221 | Z4: 0.24225 | AA4: 3.7349 | AB4: 1.1566 | AC4: 7.35442 | AD4: 0.06768 | AE4: 0.02104 | AF4: 0.02213 | AG4: 0.00176 | AH4: 6e-05 | AI4: 0 | AJ4: 0 | AK4: 0 | AL4: 0 | AM4: 0 | AN4: 0 | AO4: 0 | AP4: 0 | AQ4: 0.07448 | AR4: 0.02334 | AS4: 0.00081 | AT4: 0 | AU4: 0 | AV4: 0.04325 | AW4: 0.00695 | AX4: 0.00037 | AY4: 1e-05 | AZ4: 0 | BA4: 0 | BB4: 0 | BC4: 0 | BD4: 0 | BE4: 0 | BF4: 0 | BG4: 0.0022 | BH4: 0.07217 | BI4: 0 | BJ4: 0.0022 | BK4: 0.00713 | BL4: 0 | BM4: 5e-05 | BN4: 0 | BO4: 0 | BP4: 7e-05 | BQ4: 7 | BR4: 4.9286768 | BS4: 3.2744971 | BT4: 2.8609522 | BU4: 4.8846826 | BV4: 5.9669385 | BW4: 6.8380225 | BX4: 7.6475146 | BY4: 8.1138525 | BZ4: 8.3074268 | CA4: 8.4658057 | CB4: 8.6065869 | CC4: 8.7297705 | CD4: 8.8353565 | CE4: 8.9145459 | CF4: 0 | CG4: 1771.0788 | CH4: 1657.4886 | CI4: 1.80589 | CJ4: 0.27942 | CK4: 0.60017 | CL4: 2.68548 | CM4: 3.9379 | CN4: 70.35948 | CO4: 0 | CP4: 0 | CQ4: 0.01162 | CR4: 0.40123 | CS4: 0.19175 | CT4: 3.29209 | CU4: 24.8694 | CV4: 1.13817 | CW4: 0 | CX4: 1 | CY4: 1e-05 | CZ4: 0.07735 | DA4: 1e-05 | DB4: 0 | DC4: 0 | DD4: 1 | DE4: 0 | DF4: 0.06274 | DG4: 0.00523 | DH4: 0 | DI4: 0.0069 | DJ4: 0 | DK4: 70.94364 | DL4: 10.54865 | DM4: 0.00869 | DN4: 0.2876 | DO4: 4e-05 | DP4: 0.02329 | DQ4: 0 | DR4: 0 | DS4: 3.08133 | DT4: 3.93354 | DU4: 0.00064 | DV4: 41.51959 | DW4: 0.0025631388 | DX4: 0 | DY4: 1.08717 | DZ4: 1 | EA4: 130.58247 | EB4: 87.47021 | EC4: 0.13896 | ED4: 0 | EE4: 1.72564 | EF4: 0.42527 | EG4: 3.20663 | EH4: 0.00343 | EI4: 0.06358 | EJ4: 15.82398 | EK4: 15.83315 | EL4: 0.01382 | EM4: 0.00114 | EN4: 0.04396 | EO4: 83.02824 | EP4: 0.00661 | EQ4: 0.2053 | ER4: 0.00835 | ES4: 2.73014 | ET4: 8.80898 | EU4: 100 | EV4: 11.27363 | EW4: Nan | EX4: 0 | EY4: 0.9194
A5: 4 | B5: 0 | C5: 9.7582293 | D5: 33.035692 | E5: 2.676263 | F5: 16.887889 | G5: 19.421495 | H5: 24.020767 | I5: 23.190649 | J5: 22.460638 | K5: 21.760462 | L5: 21.071278 | M5: 20.407016 | N5: 19.767444 | O5: 19.159193 | P5: 18.593222 | Q5: 866.4281 | R5: 0 | S5: 226.74005 | T5: 0.01809 | U5: 0.13139 | V5: 2.59123 | W5: 4.57353 | X5: 0.00038 | Y5: 1.52222 | Z5: 0.88446 | AA5: 3.91723 | AB5: 1.27815 | AC5: 6.93462 | AD5: 0.22706 | AE5: 0.01927 | AF5: 0.06621 | AG5: 0.00794 | AH5: 0.00045 | AI5: 2e-05 | AJ5: 0 | AK5: 0 | AL5: 0 | AM5: 0 | AN5: 0 | AO5: 0 | AP5: 0 | AQ5: 0.07448 | AR5: 0.06624 | AS5: 0.00474 | AT5: 0 | AU5: 0 | AV5: 0.09606 | AW5: 0.01541 | AX5: 0.0018 | AY5: 9e-05 | AZ5: 0 | BA5: 0 | BB5: 0 | BC5: 0 | BD5: 0 | BE5: 0 | BF5: 0 | BG5: 0.0022 | BH5: 0.07217 | BI5: 0 | BJ5: 0.0022 | BK5: 0.01241 | BL5: 0 | BM5: 5e-05 | BN5: 0 | BO5: 0 | BP5: 0.00015 | BQ5: 7 | BR5: 4.9286768 | BS5: 3.6176514 | BT5: 2.9841357 | BU5: 4.6823096 | BV5: 5.9053467 | BW5: 6.8292236 | BX5: 7.6475146 | BY5: 8.1138525 | BZ5: 8.3074268 | CA5: 8.4658057 | CB5: 8.6065869 | CC5: 8.7297705 | CD5: 8.8353565 | CE5: 8.9233447 | CF5: 0 | CG5: 1694.4352 | CH5: 1411.1969 | CI5: 0.92512 | CJ5: 2.33295 | CK5: 0.79033 | CL5: 4.0484 | CM5: 3.96147 | CN5: 70.89711 | CO5: 0 | CP5: 0 | CQ5: 0.08113 | CR5: 1.1655 | CS5: 0.20495 | CT5: 3.31849 | CU5: 17.50742 | CV5: 2.94924 | CW5: 0 | CX5: 1 | CY5: 0.00054 | CZ5: 0.07908 | DA5: 5e-05 | DB5: 0 | DC5: 0 | DD5: 1 | DE5: 0 | DF5: 0.06272 | DG5: 0.01222 | DH5: 0 | DI5: 0.0142 | DJ5: 0 | DK5: 71.36814 | DL5: 10.62925 | DM5: 0.06026 | DN5: 0.27032 | DO5: 0.00028 | DP5: 0.02329 | DQ5: 1e-05 | DR5: 0 | DS5: 3.08246 | DT5: 3.93484 | DU5: 0.00111 | DV5: 51.82079 | DW5: 0.0025679843 | DX5: 0 | DY5: 1.34867 | DZ5: 1 | EA5: 126.11222 | EB5: 87.28135 | EC5: 0.15124 | ED5: 0 | EE5: 1.81101 | EF5: 0.41783 | EG5: 5.07236 | EH5: 0.00467 | EI5: 0.08497 | EJ5: 22.57398 | EK5: 15.83152 | EL5: 0.01386 | EM5: 0.00113 | EN5: 0.05625 | EO5: 83.17319 | EP5: 0.00642 | EQ5: 0.20518 | ER5: 0.00872 | ES5: 2.7859 | ET5: 8.78723 | EU5: 100 | EV5: 70.83307 | EW5: Nan | EX5: 0 | EY5: 0.91504
A6: 5 | B6: 0 | C6: 10.347339 | D6: 10.389362 | E6: 4.3603393 | F6: 18.201887 | G6: 19.982599 | H6: 24.122024 | I6: 23.200838 | J6: 22.460662 | K6: 21.778312 | L6: 21.070428 | M6: 20.405058 | N6: 19.7649 | O6: 19.155499 | P6: 18.587416 | Q6: 867.73764 | R6: 0 | S6: 228.72962 | T6: 0.05596 | U6: 0.5121 | V6: 3.38855 | W6: 6.57004 | X6: 0.00054 | Y6: 1.52222 | Z6: 1.78955 | AA6: 4.1514 | AB6: 1.43427 | AC6: 6.66266 | AD6: 0.09031 | AE6: 0.03846 | AF6: 0.11084 | AG6: 0.01941 | AH6: 0.0016 | AI6: 8e-05 | AJ6: 0 | AK6: 0 | AL6: 0 | AM6: 0 | AN6: 0 | AO6: 0 | AP6: 0 | AQ6: 0.07448 | AR6: 0.11687 | AS6: 0.01552 | AT6: 0 | AU6: 0 | AV6: 0.15427 | AW6: 0.02604 | AX6: 0.00373 | AY6: 0.00033 | AZ6: 2e-05 | BA6: 0 | BB6: 0 | BC6: 0 | BD6: 0 | BE6: 0 | BF6: 0 | BG6: 0.0022 | BH6: 0.07217 | BI6: 0 | BJ6: 0.0022 | BK6: 0.0158 | BL6: 0 | BM6: 5e-05 | BN6: 0 | BO6: 0 | BP6: 0.00021 | BQ6: 7 | BR6: 4.9286768 | BS6: 3.4768701 | BT6: 2.9577393 | BU6: 4.9374756 | BV6: 5.8437549 | BW6: 6.811626 | BX6: 7.6387158 | BY6: 8.1138525 | BZ6: 8.3074268 | CA6: 8.4658057 | CB6: 8.6065869 | CC6: 8.7297705 | CD6: 8.8353565 | CE6: 8.9233447 | CF6: 0 | CG6: 1717.8746 | CH6: 1527.7811 | CI6: 0.60564 | CJ6: 3.2084 | CK6: 1.42247 | CL6: 5.23651 | CM6: 4.00998 | CN6: 72.13163 | CO6: 0 | CP6: 0 | CQ6: 0.21035 | CR6: 1.88143 | CS6: 0.17709 | CT6: 3.21291 | CU6: 50.17343 | CV6: 1.08383 | CW6: 0 | CX6: 1 | CY6: 0.00296 | CZ6: 0.08663 | DA6: 0.00013 | DB6: 0 | DC6: 0 | DD6: 1 | DE6: 0 | DF6: 0.06271 | DG6: 0.01881 | DH6: 0 | DI6: 0.0212 | DJ6: 0 | DK6: 72.24209 | DL6: 10.81434 | DM6: 0.21725 | DN6: 0.25523 | DO6: 0.00076 | DP6: 0.02329 | DQ6: 2e-05 | DR6: 19.66789 | DS6: 3.08646 | DT6: 3.93939 | DU6: 0.00142 | DV6: 65.05109 | DW6: 0.0025728731 | DX6: 0 | DY6: 1.51323 | DZ6: 1 | EA6: 120.24393 | EB6: 86.54668 | EC6: 0.16543 | ED6: 0 | EE6: 2.03236 | EF6: 0.41946 | EG6: 6.96961 | EH6: 0.00609 | EI6: 0.10658 | EJ6: 29.32604 | EK6: 15.81606 | EL6: 0.01389 | EM6: 0.00113 | EN6: 0.07052 | EO6: 83.33214 | EP6: 0.00629 | EQ6: 0.20504 | ER6: 0.00913 | ES6: 2.86551 | ET6: 8.71413 | EU6: 100 | EV6: 190.98604 | EW6: Nan | EX6: 0 | EY6: 0.95498
A7: 6 | B7: 0 | C7: 10.868729 | D7: 23.736779 | E7: 6.4702116 | F7: 18.781783 | G7: 20.595556 | H7: 24.259956 | I7: 23.219876 | J7: 22.461865 | K7: 21.828803 | L7: 21.07091 | M7: 20.402023 | N7: 19.761214 | O7: 19.150771 | P7: 18.58074 | Q7: 869.01732 | R7: 0 | S7: 230.1135 | T7: 0.11367 | U7: 1.25525 | V7: 3.38374 | W7: 10.06357 | X7: 0.00109 | Y7: 1.52222 | Z7: 2.88844 | AA7: 4.33023 | AB7: 1.55348 | AC7: 6.44296 | AD7: 0.24588 | AE7: 0.0629 | AF7: 0.14872 | AG7: 0.0359 | AH7: 0.00389 | AI7: 0.00024 | AJ7: 1e-05 | AK7: 0 | AL7: 0 | AM7: 0 | AN7: 0 | AO7: 0 | AP7: 0 | AQ7: 0.07448 | AR7: 0.16831 | AS7: 0.0337 | AT7: 0 | AU7: 0 | AV7: 0.21456 | AW7: 0.04 | AX7: 0.00549 | AY7: 0.00071 | AZ7: 6e-05 | BA7: 0 | BB7: 0 | BC7: 0 | BD7: 0 | BE7: 0 | BF7: 0 | BG7: 0.0022 | BH7: 0.07217 | BI7: 0 | BJ7: 0.0022 | BK7: 0.01852 | BL7: 0 | BM7: 5e-05 | BN7: 1e-05 | BO7: 0 | BP7: 0.00028 | BQ7: 7 | BR7: 4.9286768 | BS7: 3.1073193 | BT7: 2.8785498 | BU7: 4.8406885 | BV7: 5.7909619 | BW7: 6.7852295 | BX7: 7.629917 | BY7: 8.1138525 | BZ7: 8.3074268 | CA7: 8.4746045 | CB7: 8.6065869 | CC7: 8.7297705 | CD7: 8.8353565 | CE7: 8.9233447 | CF7: 0 | CG7: 1772.4979 | CH7: 1593.1942 | CI7: 4.36444 | CJ7: 0.71649 | CK7: 1.22253 | CL7: 6.30346 | CM7: 4.08208 | CN7: 74.19505 | CO7: 0 | CP7: 0 | CQ7: 0.33089 | CR7: 2.41417 | CS7: 0.20348 | CT7: 3.15131 | CU7: 46.35151 | CV7: 2.31551 | CW7: 0 | CX7: 1 | CY7: 0.00655 | CZ7: 0.09784 | DA7: 0.0002 | DB7: 0 | DC7: 0 | DD7: 1 | DE7: 0 | DF7: 0.06269 | DG7: 0.02544 | DH7: 0 | DI7: 0.02768 | DJ7: 0 | DK7: 73.54102 | DL7: 11.1237 | DM7: 0.41632 | DN7: 0.2456 | DO7: 0.00148 | DP7: 0.0233 | DQ7: 4e-05 | DR7: 0 | DS7: 3.09512 | DT7: 3.94924 | DU7: 0.00166 | DV7: 75.16034 | DW7: 0.0025778354 | DX7: 0 | DY7: 1.64973 | DZ7: 1 | EA7: 113.22965 | EB7: 84.98058 | EC7: 0.17661 | ED7: 0 | EE7: 1.81141 | EF7: 0.42076 | EG7: 8.85454 | EH7: 0.00768 | EI7: 0.12844 | EJ7: 36.0811 | EK7: 15.78793 | EL7: 0.01392 | EM7: 0.00114 | EN7: 0.08187 | EO7: 83.50378 | EP7: 0.0062 | EQ7: 0.20486 | ER7: 0.00942 | ES7: 2.93769 | ET7: 8.56522 | EU7: 100 | EV7: 364.18429 | EW7: Nan | EX7: 0 | EY7: 0.9527
A8: 7 | B8: 0 | C8: 11.349565 | D8: 54.474247 | E8: 3.1672491 | F8: 20.150344 | G8: 21.193052 | H8: 24.430472 | I8: 23.249467 | J8: 22.464946 | K8: 21.925337 | L8: 21.07491 | M8: 20.397603 | N8: 19.755844 | O8: 19.14447 | P8: 18.572683 | Q8: 870.25349 | R8: 0 | S8: 232.35913 | T8: 0.18306 | U8: 2.35692 | V8: 4.09059 | W8: 13.52308 | X8: 0.00243 | Y8: 1.52223 | Z8: 4.14703 | AA8: 4.55237 | AB8: 1.70158 | AC8: 6.2574 | AD8: 0.59158 | AE8: 0.03186 | AF8: 0.19366 | AG8: 0.05633 | AH8: 0.00757 | AI8: 0.00059 | AJ8: 4e-05 | AK8: 0 | AL8: 0 | AM8: 0 | AN8: 0 | AO8: 0 | AP8: 0 | AQ8: 0.07448 | AR8: 0.21778 | AS8: 0.05893 | AT8: 0 | AU8: 0 | AV8: 0.275 | AW8: 0.05749 | AX8: 0.00733 | AY8: 0.00114 | AZ8: 0.00013 | BA8: 1e-05 | BB8: 0 | BC8: 0 | BD8: 0 | BE8: 0 | BF8: 0 | BG8: 0.0022 | BH8: 0.07217 | BI8: 0 | BJ8: 0.0022 | BK8: 0.02081 | BL8: 0 | BM8: 5e-05 | BN8: 1e-05 | BO8: 0 | BP8: 0.00033 | BQ8: 7 | BR8: 4.9286768 | BS8: 3.3448877 | BT8: 2.8873486 | BU8: 4.814292 | BV8: 5.7733643 | BW8: 6.758833 | BX8: 7.6123193 | BY8: 8.1138525 | BZ8: 8.3074268 | CA8: 8.4746045 | CB8: 8.6153857 | CC8: 8.7297705 | CD8: 8.8353565 | CE8: 8.9233447 | CF8: 0 | CG8: 1744.074 | CH8: 1446.6511 | CI8: 1.75158 | CJ8: 4.65637 | CK8: 0.92866 | CL8: 7.33661 | CM8: 4.17466 | CN8: 77.18059 | CO8: 0 | CP8: 0 | CQ8: 0.50757 | CR8: 3.15587 | CS8: 0.18735 | CT8: 3.00173 | CU8: 29.36192 | CV8: 5.17603 | CW8: 0 | CX8: 1 | CY8: 0.0107 | CZ8: 0.11077 | DA8: 0.00026 | DB8: 0 | DC8: 0 | DD8: 1 | DE8: 0 | DF8: 0.06266 | DG8: 0.03204 | DH8: 0 | DI8: 0.03396 | DJ8: 0 | DK8: 75.20895 | DL8: 11.5713 | DM8: 0.8003 | DN8: 0.23292 | DO8: 0.0024 | DP8: 0.02331 | DQ8: 6e-05 | DR8: 0 | DS8: 3.10987 | DT8: 3.96598 | DU8: 0.00187 | DV8: 87.74085 | DW8: 0.0025828985 | DX8: 0 | DY8: 1.76429 | DZ8: 1 | EA8: 105.24528 | EB8: 82.52414 | EC8: 0.18503 | ED8: 0 | EE8: 1.80729 | EF8: 0.42185 | EG8: 10.76873 | EH8: 0.00941 | EI8: 0.15051 | EJ8: 42.83657 | EK8: 15.75034 | EL8: 0.01395 | EM8: 0.00116 | EN8: 0.09052 | EO8: 83.68503 | EP8: 0.00614 | EQ8: 0.20462 | ER8: 0.00963 | ES8: 2.97886 | ET8: 8.32987 | EU8: 100 | EV8: 578.21148 | EW8: Nan | EX8: 0 | EY8: 0.95191
A9: 8 | B9: 0 | C9: 11.970026 | D9: 16.198316 | E9: 5.3668317 | F9: 20.6696 | G9: 21.755695 | H9: 24.626751 | I9: 23.290662 | J9: 22.470646 | K9: 22.072128 | L9: 21.085074 | M9: 20.391967 | N9: 19.748572 | O9: 19.136347 | P9: 18.563001 | Q9: 871.4399 | R9: 0 | S9: 233.81044 | T9: 0.25808 | U9: 3.77282 | V9: 4.19146 | W9: 15.31216 | X9: 0.0051 | Y9: 1.52223 | Z9: 5.54046 | AA9: 4.77241 | AB9: 1.84827 | AC9: 6.10054 | AD9: 0.18675 | AE9: 0.06068 | AF9: 0.22606 | AG9: 0.07957 | AH9: 0.01278 | AI9: 0.00118 | AJ9: 9e-05 | AK9: 1e-05 | AL9: 0 | AM9: 0 | AN9: 0 | AO9: 0 | AP9: 0 | AQ9: 0.07448 | AR9: 0.26409 | AS9: 0.09035 | AT9: 0 | AU9: 0 | AV9: 0.33419 | AW9: 0.07898 | AX9: 0.0094 | AY9: 0.00156 | AZ9: 0.00024 | BA9: 2e-05 | BB9: 0 | BC9: 0 | BD9: 0 | BE9: 0 | BF9: 0 | BG9: 0.0022 | BH9: 0.07217 | BI9: 0 | BJ9: 0.0022 | BK9: 0.02275 | BL9: 1e-05 | BM9: 5e-05 | BN9: 1e-05 | BO9: 0 | BP9: 0.00038 | BQ9: 7 | BR9: 4.9286768 | BS9: 3.2129053 | BT9: 2.816958 | BU9: 5.3950147 | BV9: 5.7909619 | BW9: 6.7236377 | BX9: 7.5947217 | BY9: 8.1138525 | BZ9: 8.3074268 | CA9: 8.4746045 | CB9: 8.6153857 | CC9: 8.7297705 | CD9: 8.8353565 | CE9: 8.9233447 | CF9: 0 | CG9: 1742.7323 | CH9: 1616.2826 | CI9: 0.96285 | CJ9: 5.5526 | CK9: 1.87574 | CL9: 8.3912 | CM9: 4.28417 | CN9: 81.16686 | CO9: 0 | CP9: 0 | CQ9: 0.67729 | CR9: 3.8563 | CS9: 0.10083 | CT9: 2.94014 | CU9: 77.76367 | CV9: 1.61075 | CW9: 0 | CX9: 1 | CY9: 0.0156 | CZ9: 0.12607 | DA9: 0.00034 | DB9: 0 | DC9: 0 | DD9: 1 | DE9: 0 | DF9: 0.06264 | DG9: 0.03856 | DH9: 0 | DI9: 0.04124 | DJ9: 0 | DK9: 77.18191 | DL9: 12.16894 | DM9: 1.26496 | DN9: 0.22222 | DO9: 0.00349 | DP9: 0.02332 | DQ9: 8e-05 | DR9: 18.6408 | DS9: 3.13168 | DT9: 3.99077 | DU9: 0.00204 | DV9: 100.34173 | DW9: 0.0025880856 | DX9: 0 | DY9: 1.85682 | DZ9: 1 | EA9: 96.61936 | EB9: 79.31528 | EC9: 0.19181 | ED9: 0 | EE9: 2.04864 | EF9: 0.42315 | EG9: 12.67857 | EH9: 0.01125 | EI9: 0.17277 | EJ9: 49.58635 | EK9: 15.70557 | EL9: 0.01397 | EM9: 0.00118 | EN9: 0.09756 | EO9: 83.87378 | EP9: 0.00611 | EQ9: 0.20431 | ER9: 0.0098 | ES9: 2.9691 | ET9: 8.01007 | EU9: 100 | EV9: 820.79511 | EW9: Nan | EX9: 0 | EY9: 0.99715
A10: 9 | B10: 0 | C10: 12.509216 | D10: 34.614985 | E10: 8.4102749 | F10: 20.528152 | G10: 22.286019 | H10: 24.840206 | I10: 23.343962 | J10: 22.479684 | K10: 22.266284 | L10: 21.103784 | M10: 20.385657 | N10: 19.739464 | O10: 19.126403 | P10: 18.551679 | Q10: 872.57659 | R10: 0 | S10: 234.65129 | T10: 0.3354 | U10: 5.45881 | V10: 3.73772 | W10: 18.50266 | X10: 0.00982 | Y10: 1.52224 | Z10: 7.04977 | AA10: 4.92605 | AB10: 1.9507 | AC10: 5.96576 | AD10: 0.44037 | AE10: 0.09848 | AF10: 0.2464 | AG10: 0.10485 | AH10: 0.01956 | AI10: 0.00208 | AJ10: 0.00018 | AK10: 1e-05 | AL10: 0 | AM10: 0 | AN10: 0 | AO10: 0 | AP10: 0 | AQ10: 0.07448 | AR10: 0.30683 | AS10: 0.12701 | AT10: 0 | AU10: 0 | AV10: 0.39099 | AW10: 0.10446 | AX10: 0.01166 | AY10: 0.00194 | AZ10: 0.00036 | BA10: 4e-05 | BB10: 0 | BC10: 0 | BD10: 0 | BE10: 0 | BF10: 0 | BG10: 0.0022 | BH10: 0.07217 | BI10: 0 | BJ10: 0.0022 | BK10: 0.0244 | BL10: 1e-05 | BM10: 5e-05 | BN10: 2e-05 | BO10: 0 | BP10: 0.00043 | BQ10: 7 | BR10: 4.9286768 | BS10: 2.8873486 | BT10: 2.816958 | BU10: 5.3598193 | BV10: 5.8173584 | BW10: 6.6972412 | BX10: 7.5595264 | BY10: 8.1138525 | BZ10: 8.3074268 | CA10: 8.4746045 | CB10: 8.6153857 | CC10: 8.7385693 | CD10: 8.8353565 | CE10: 8.9233447 | CF10: 0 | CG10: 1837.6818 | CH10: 1645.0327 | CI10: 6.76542 | CJ10: 1.16933 | CK10: 1.4126 | CL10: 9.34736 | CM10: 4.40694 | CN10: 86.22518 | CO10: 0 | CP10: 0 | CQ10: 0.80726 | CR10: 4.39664 | CS10: 0.13309 | CT10: 2.94894 | CU10: 68.10054 | CV10: 3.24614 | CW10: 0 | CX10: 1 | CY10: 0.02112 | CZ10: 0.14329 | DA10: 0.00042 | DB10: 0 | DC10: 0 | DD10: 1 | DE10: 0 | DF10: 0.0626 | DG10: 0.04514 | DH10: 0 | DI10: 0.04747 | DJ10: 0 | DK10: 79.39353 | DL10: 12.92731 | DM10: 1.677 | DN10: 0.21474 | DO10: 0.00474 | DP10: 0.02335 | DQ10: 0.00011 | DR10: 0 | DS10: 3.1611 | DT10: 4.02427 | DU10: 0.00219 | DV10: 109.50053 | DW10: 0.0025934154 | DX10: 0 | DY10: 1.93917 | DZ10: 1 | EA10: 87.70444 | EB10: 75.58437 | EC10: 0.19754 | ED10: 0 | EE10: 1.81896 | EF10: 0.42417 | EG10: 14.56859 | EH10: 0.01317 | EI10: 0.19521 | EJ10: 56.33849 | EK10: 15.65502 | EL10: 0.014 | EM10: 0.00121 | EN10: 0.10359 | EO10: 84.0687 | EP10: 0.00608 | EQ10: 0.20394 | ER10: 0.00994 | ES10: 2.8924 | ET10: 7.61714 | EU10: 100 | EV10: 1081.3898 | EW10: Nan | EX10: 0 | EY10: 0.99858
A11: 10 | B11: 0 | C11: 13.061382 | D11: 75.930848 | E11: 3.5613688 | F11: 21.226005 | G11: 22.748376 | H11: 25.062441 | I11: 23.409255 | J11: 22.492719 | K11: 22.501405 | L11: 21.132828 | M11: 20.379404 | N11: 19.72876 | O11: 19.11478 | P11: 18.53883 | Q11: 873.66711 | R11: 0 | S11: 236.3348 | T11: 0.4132 | U11: 7.3778 | V11: 4.20477 | W11: 21.52665 | X11: 0.01745 | Y11: 1.52224 | Z11: 8.65923 | AA11: 5.16998 | AB11: 2.11332 | AC11: 5.84716 | AD11: 0.98307 | AE11: 0.0406 | AF11: 0.27409 | AG11: 0.13112 | AH11: 0.0279 | AI11: 0.00336 | AJ11: 0.00033 | AK11: 3e-05 | AL11: 0 | AM11: 0 | AN11: 0 | AO11: 0 | AP11: 0 | AQ11: 0.07448 | AR11: 0.34591 | AS11: 0.16779 | AT11: 0 | AU11: 0 | AV11: 0.44462 | AW11: 0.13379 | AX11: 0.01415 | AY11: 0.00231 | AZ11: 0.0005 | BA11: 8e-05 | BB11: 1e-05 | BC11: 0 | BD11: 0 | BE11: 0 | BF11: 0 | BG11: 0.0022 | BH11: 0.07217 | BI11: 0 | BJ11: 0.0022 | BK11: 0.02584 | BL11: 1e-05 | BM11: 5e-05 | BN11: 2e-05 | BO11: 0 | BP11: 0.00047 | BQ11: 7 | BR11: 4.9286768 | BS11: 2.922544 | BT11: 2.8257568 | BU11: 5.2982275 | BV11: 5.8613525 | BW11: 6.6708447 | BX11: 7.524331 | BY11: 8.1138525 | BZ11: 8.3074268 | CA11: 8.4746045 | CB11: 8.6153857 | CC11: 8.7385693 | CD11: 8.8441553 | CE11: 8.9321435 | CF11: 0 | CG11: 1828.9085 | CH11: 1479.7482 | CI11: 2.33742 | CJ11: 6.9678 | CK11: 0.95192 | CL11: 10.25715 | CM11: 4.53905 | CN11: 92.41688 | CO11: 0 | CP11: 0 | CQ11: 0.98516 | CR11: 5.13859 | CS11: 0.10083 | CT11: 2.87855 | CU11: 42.0711 | CV11: 6.85839 | CW11: 0 | CX11: 1 | CY11: 0.02713 | CZ11: 0.16197 | DA11: 0.0005 | DB11: 0 | DC11: 0 | DD11: 1 | DE11: 0 | DF11: 0.06257 | DG11: 0.05178 | DH11: 0 | DI11: 0.05349 | DJ11: 0 | DK11: 81.77371 | DL11: 13.8556 | DM11: 2.31198 | DN11: 0.20516 | DO11: 0.0061 | DP11: 0.02337 | DQ11: 0.00014 | DR11: 0 | DS11: 3.1983 | DT11: 4.06675 | DU11: 0.00232 | DV11: 124.12664 | DW11: 0.0025989019 | DX11: 0 | DY11: 2.0106 | DZ11: 1 | EA11: 78.81238 | EB11: 71.5672 | EC11: 0.20247 | ED11: 0 | EE11: 1.80782 | EF11: 0.42514 | EG11: 16.48812 | EH11: 0.01517 | EI11: 0.21778 | EJ11: 63.08244 | EK11: 15.59967 | EL11: 0.01403 | EM11: 0.00124 | EN11: 0.10885 | EO11: 84.26891 | EP11: 0.00607 | EQ11: 0.20351 | ER11: 0.01006 | ES11: 2.76057 | ET11: 6.92708 | EU11: 100 | EV11: 1351.7961 | EW11: Nan | EX11: 0 | EY11: 1.00117
A12: 11 | B12: 0 | C12: 9.7272454 | D12: 22.169302 | E12: 6.3821844 | F12: 21.245843 | G12: 23.141267 | H12: 25.285405 | I12: 23.485719 | J12: 22.510312 | K12: 22.770063 | L12: 21.173379 | M12: 20.373994 | N12: 19.716778 | O12: 19.101683 | P12: 18.524627 | Q12: 874.71651 | R12: 0 | S12: 237.32907 | T12: 0.4903 | U12: 9.49627 | V12: 4.18267 | W12: 22.87899 | X12: 0.02901 | Y12: 1.52224 | Z12: 10.35629 | AA12: 5.38156 | AB12: 2.25437 | AC12: 5.74367 | AD12: 0.29134 | AE12: 0.08047 | AF12: 0.29076 | AG12: 0.15754 | AH12: 0.03771 | AI12: 0.00505 | AJ12: 0.00056 | AK12: 6e-05 | AL12: 0 | AM12: 0 | AN12: 0 | AO12: 0 | AP12: 0 | AQ12: 0.07448 | AR12: 0.38145 | AS12: 0.21154 | AT12: 0 | AU12: 0 | AV12: 0.49471 | AW12: 0.16664 | AX12: 0.01686 | AY12: 0.00269 | AZ12: 0.00063 | BA12: 0.00012 | BB12: 1e-05 | BC12: 0 | BD12: 0 | BE12: 0 | BF12: 0 | BG12: 0.0022 | BH12: 0.07217 | BI12: 0 | BJ12: 0.0022 | BK12: 0.02708 | BL12: 1e-05 | BM12: 5e-05 | BN12: 3e-05 | BO12: 0 | BP12: 0.00052 | BQ12: 7 | BR12: 4.9286768 | BS12: 2.9753369 | BT12: 2.7377686 | BU12: 5.7909619 | BV12: 5.8965479 | BW12: 6.6444482 | BX12: 7.4803369 | BY12: 8.1050537 | BZ12: 8.3074268 | CA12: 8.4746045 | CB12: 8.6153857 | CC12: 8.7385693 | CD12: 8.8441553 | CE12: 8.9321435 | CF12: 0 | CG12: 1778.9518 | CH12: 1660.3003 | CI12: 1.27674 | CJ12: 7.78331 | CK12: 2.27926 | CL12: 11.33931 | CM12: 4.67621 | CN12: 99.78186 | CO12: 0 | CP12: 0 | CQ12: 1.14935 | CR12: 5.82413 | CS12: 0.03484 | CT12: 2.83456 | CU12: 107.10136 | CV12: 1.91052 | CW12: 0 | CX12: 1 | CY12: 0.03347 | CZ12: 0.18168 | DA12: 0.00059 | DB12: 0 | DC12: 0 | DD12: 1 | DE12: 0 | DF12: 0.06253 | DG12: 0.05824 | DH12: 1e-05 | DI12: 0.06098 | DJ12: 1e-05 | DK12: 84.24467 | DL12: 14.9598 | DM12: 2.96162 | DN12: 0.19709 | DO12: 0.00755 | DP12: 0.0234 | DQ12: 0.00018 | DR12: 17.38461 | DS12: 3.24304 | DT12: 4.11806 | DU12: 0.00243 | DV12: 138.18851 | DW12: 0.0026045541 | DX12: 0 | DY12: 2.06902 | DZ12: 1 | EA12: 70.18966 | EB12: 67.45823 | EC12: 0.2068 | ED12: 0 | EE12: 2.06953 | EF12: 0.41774 | EG12: 18.40304 | EH12: 0.01725 | EI12: 0.24049 | EJ12: 69.83062 | EK12: 15.54025 | EL12: 0.01405 | EM12: 0.00127 | EN12: 0.11353 | EO12: 84.47373 | EP12: 0.00606 | EQ12: 0.20302 | ER12: 0.01017 | ES12: 2.61466 | ET12: 5.66427 | EU12: 100 | EV12: 1626.3524 | EW12: Nan | EX12: 0 | EY12: 1.04643
A13: 12 | B13: 0 | C13: 10.186339 | D13: 46.311346 | E13: 10.451536 | F13: 20.705647 | G13: 23.480032 | H13: 25.501537 | I13: 23.571919 | J13: 22.532893 | K13: 23.065096 | L13: 21.226098 | M13: 20.370193 | N13: 19.70387 | O13: 19.087335 | P13: 18.509255 | Q13: 875.73006 | R13: 0 | S13: 237.75387 | T13: 0.56605 | U13: 11.78391 | V13: 3.65486 | W13: 25.59842 | X13: 0.04561 | Y13: 1.52225 | Z13: 12.13116 | AA13: 5.46595 | AB13: 2.31064 | AC13: 5.65163 | AD13: 0.64757 | AE13: 0.13399 | AF13: 0.29788 | AG13: 0.18393 | AH13: 0.04889 | AI13: 0.0072 | AJ13: 0.00087 | AK13: 0.0001 | AL13: 1e-05 | AM13: 0 | AN13: 0 | AO13: 0 | AP13: 0 | AQ13: 0.07448 | AR13: 0.41363 | AS13: 0.25717 | AT13: 0 | AU13: 0 | AV13: 0.54101 | AW13: 0.20239 | AX13: 0.01976 | AY13: 0.00308 | AZ13: 0.00077 | BA13: 0.00017 | BB13: 2e-05 | BC13: 0 | BD13: 0 | BE13: 0 | BF13: 0 | BG13: 0.0022 | BH13: 0.07217 | BI13: 0 | BJ13: 0.0022 | BK13: 0.02818 | BL13: 1e-05 | BM13: 5e-05 | BN13: 4e-05 | BO13: 0 | BP13: 0.00057 | BQ13: 7 | BR13: 4.9286768 | BS13: 2.7993604 | BT13: 2.7553662 | BU13: 5.6149854 | BV13: 5.9229443 | BW13: 6.6180518 | BX13: 7.4363428 | BY13: 8.0962549 | BZ13: 8.3074268 | CA13: 8.4746045 | CB13: 8.6241846 | CC13: 8.7385693 | CD13: 8.8441553 | CE13: 8.9321435 | CF13: 0 | CG13: 1859.539 | CH13: 1675.6046 | CI13: 9.04356 | CJ13: 1.56557 | CK13: 1.61848 | CL13: 12.22761 | CM13: 4.81346 | CN13: 108.31716 | CO13: 0 | CP13: 0 | CQ13: 1.27234 | CR13: 6.35188 | CS13: 0.07883 | CT13: 2.81696 | CU13: 91.02926 | CV13: 4.08978 | CW13: 0 | CX13: 1 | CY13: 0.04001 | CZ13: 0.20196 | DA13: 0.00069 | DB13: 0 | DC13: 0 | DD13: 1 | DE13: 0 | DF13: 0.06248 | DG13: 0.06454 | DH13: 1e-05 | DI13: 0.06674 | DJ13: 1e-05 | DK13: 86.71731 | DL13: 16.23945 | DM13: 3.47929 | DN13: 0.19299 | DO13: 0.00909 | DP13: 0.02344 | DQ13: 0.00022 | DR13: 0 | DS13: 3.2947 | DT13: 4.1776 | DU13: 0.00253 | DV13: 146.12187 | DW13: 0.0026103756 | DX13: 0 | DY13: 2.12321 | DZ13: 1 | EA13: 62.01899 | EB13: 63.39554 | EC13: 0.21066 | ED13: 0 | EE13: 1.8246 | EF13: 0.41903 | EG13: 20.29874 | EH13: 0.01938 | EI13: 0.26332 | EJ13: 76.58871 | EK13: 15.47734 | EL13: 0.01408 | EM13: 0.00131 | EN13: 0.11777 | EO13: 84.68261 | EP13: 0.00605 | EQ13: 0.20249 | ER13: 0.01026 | ES13: 2.48205 | ET13: 4.63167 | EU13: 100 | EV13: 1901.9087 | EW13: Nan | EX13: 0 | EY13: 1.0495
A14: 13 | B14: 0 | C14: 10.784229 | D14: 99.70304 | E14: 3.9870292 | F14: 21.057272 | G14: 23.742434 | H14: 25.704519 | I14: 23.665965 | J14: 22.560721 | K14: 23.380198 | L14: 21.291255 | M14: 20.368707 | N14: 19.690385 | O14: 19.071953 | P14: 18.49289 | Q14: 876.71269 | R14: 0 | S14: 239.0263 | T14: 0.6403 | U14: 14.21558 | V14: 4.08324 | W14: 28.17965 | X14: 0.06846 | Y14: 1.52225 | Z14: 13.97582 | AA14: 5.66279 | AB14: 2.44186 | AC14: 5.56749 | AD14: 1.39544 | AE14: 0.04868 | AF14: 0.3169 | AG14: 0.20988 | AH14: 0.06133 | AI14: 0.00983 | AJ14: 0.00129 | AK14: 0.00016 | AL14: 1e-05 | AM14: 0 | AN14: 0 | AO14: 0 | AP14: 0 | AQ14: 0.07448 | AR14: 0.44269 | AS14: 0.30368 | AT14: 0 | AU14: 0 | AV14: 0.58349 | AW14: 0.24039 | AX14: 0.02284 | AY14: 0.00347 | AZ14: 0.0009 | BA14: 0.00022 | BB14: 3e-05 | BC14: 0 | BD14: 0 | BE14: 0 | BF14: 0 | BG14: 0.0022 | BH14: 0.07217 | BI14: 0 | BJ14: 0.0022 | BK14: 0.02916 | BL14: 1e-05 | BM14: 5e-05 | BN14: 5e-05 | BO14: 0 | BP14: 0.00061 | BQ14: 7 | BR14: 4.9286768 | BS14: 2.9401416 | BT14: 2.764165 | BU14: 5.4566064 | BV14: 5.9493408 | BW14: 6.6004541 | BX14: 7.3835498 | BY14: 8.0962549 | BZ14: 8.3074268 | CA14: 8.4834033 | CB14: 8.6241846 | CC14: 8.7473682 | CD14: 8.8441553 | CE14: 8.9321435 | CF14: 0 | CG14: 1807.8599 | CH14: 1512.3318 | CI14: 3.09297 | CJ14: 8.96007 | CK14: 0.99668 | CL14: 13.04972 | CM14: 4.94551 | CN14: 117.94844 | CO14: 0 | CP14: 0 | CQ14: 1.4392 | CR14: 7.05382 | CS14: 0.07737 | CT14: 2.76417 | CU14: 54.75178 | CV14: 8.53418 | CW14: 0 | CX14: 1 | CY14: 0.04662 | CZ14: 0.22239 | DA14: 0.00079 | DB14: 0 | DC14: 0 | DD14: 1 | DE14: 0 | DF14: 0.06244 | DG14: 0.07084 | DH14: 1e-05 | DI14: 0.07217 | DJ14: 1e-05 | DK14: 89.09622 | DL14: 17.68342 | DM14: 4.21075 | DN14: 0.18728 | DO14: 0.01069 | DP14: 0.02347 | DQ14: 0.00025 | DR14: 0 | DS14: 3.35224 | DT14: 4.24437 | DU14: 0.00262 | DV14: 161.19858 | DW14: 0.0026163633 | DX14: 0 | DY14: 2.17167 | DZ14: 1 | EA14: 54.42676 | EB14: 59.46539 | EC14: 0.21415 | ED14: 0 | EE14: 1.8085 | EF14: 0.42055 | EG14: 22.22932 | EH14: 0.02157 | EI14: 0.28625 | EJ14: 83.33925 | EK14: 15.41141 | EL14: 0.0141 | EM14: 0.00135 | EN14: 0.12166 | EO14: 84.89515 | EP14: 0.00605 | EQ14: 0.20191 | ER14: 0.01036 | ES14: 2.37573 | ET14: 3.78731 | EU14: 100 | EV14: 2177.4963 | EW14: Nan | EX14: 0 | EY14: 1.05364
A15: 14 | B15: 0 | C15: 11.323706 | D15: 28.345636 | E15: 7.4005797 | F15: 20.874386 | G15: 23.935784 | H15: 25.889198 | I15: 23.765666 | J15: 22.593869 | K15: 23.7101 | L15: 21.368838 | M15: 20.370169 | N15: 19.67666 | O15: 19.055735 | P15: 18.475688 | Q15: 877.66873 | R15: 0 | S15: 239.71609 | T15: 0.7132 | U15: 16.77161 | V15: 4.07679 | W15: 29.17988 | X15: 0.09879 | Y15: 1.52226 | Z15: 15.88377 | AA15: 5.79645 | AB15: 2.53097 | AC15: 5.49149 | AD15: 0.40004 | AE15: 0.09978 | AF15: 0.32736 | AG15: 0.23506 | AH15: 0.07491 | AI15: 0.01295 | AJ15: 0.00183 | AK15: 0.00025 | AL15: 2e-05 | AM15: 0 | AN15: 0 | AO15: 0 | AP15: 0 | AQ15: 0.07448 | AR15: 0.46888 | AS15: 0.35027 | AT15: 0 | AU15: 0 | AV15: 0.62223 | AW15: 0.28003 | AX15: 0.02608 | AY15: 0.00387 | AZ15: 0.00103 | BA15: 0.00029 | BB15: 4e-05 | BC15: 1e-05 | BD15: 0 | BE15: 0 | BF15: 0 | BG15: 0.0022 | BH15: 0.07217 | BI15: 0 | BJ15: 0.0022 | BK15: 0.03004 | BL15: 1e-05 | BM15: 5e-05 | BN15: 6e-05 | BO15: 0 | BP15: 0.00067 | BQ15: 7 | BR15: 4.9286768 | BS15: 2.8873486 | BT15: 2.6585791 | BU15: 5.7821631 | BV15: 5.9669385 | BW15: 6.5828565 | BX15: 7.321958 | BY15: 8.0874561 | BZ15: 8.2986279 | CA15: 8.4834033 | CB15: 8.6241846 | CC15: 8.7473682 | CD15: 8.8529541 | CE15: 8.9409424 | CF15: 0 | CG15: 1810.2621 | CH15: 1705.9459 | CI15: 1.58032 | CJ15: 9.72263 | CK15: 2.64533 | CL15: 13.94828 | CM15: 5.06812 | CN15: 128.5145 | CO15: 0 | CP15: 0 | CQ15: 1.59405 | CR15: 7.68096 | CS15: 0.03631 | CT15: 2.72897 | CU15: 136.43461 | CV15: 2.44394 | CW15: 0 | CX15: 1 | CY15: 0.05317 | CZ15: 0.24262 | DA15: 0.0009 | DB15: 0 | DC15: 0 | DD15: 1 | DE15: 0 | DF15: 0.06239 | DG15: 0.07681 | DH15: 1e-05 | DI15: 0.07941 | DJ15: 2e-05 | DK15: 91.30512 | DL15: 19.26754 | DM15: 4.90374 | DN15: 0.18294 | DO15: 0.01235 | DP15: 0.02351 | DQ15: 0.00029 | DR15: 16.4439 | DS15: 3.41428 | DT15: 4.31696 | DU15: 0.00269 | DV15: 175.68568 | DW15: 0.0026225082 | DX15: 0 | DY15: 2.21201 | DZ15: 1 | EA15: 47.49044 | EB15: 55.71498 | EC15: 0.21737 | ED15: 0 | EE15: 2.07627 | EF15: 0.4218 | EG15: 24.15581 | EH15: 0.02382 | EI15: 0.30927 | EJ15: 90.09302 | EK15: 15.34278 | EL15: 0.01413 | EM15: 0.00139 | EN15: 0.12528 | EO15: 85.11103 | EP15: 0.00605 | EQ15: 0.20131 | ER15: 0.01044 | ES15: 2.2977 | ET15: 3.09688 | EU15: 100 | EV15: 2453.3547 | EW15: Nan | EX15: 0 | EY15: 1.05886
... A37: 36 | B37: 0 | C37: 0.90611669 | D37: 140.14114 | E37: 25.195906 | F37: 21.96261 | G37: 24.882507 | H37: 25.506934 | I37: 24.293146 | J37: 23.378282 | K37: 30.615729 | L37: 25.19688 | M37: 21.698254 | N37: 19.811701 | O37: 18.76464 | P37: 18.055458 | Q37: 895.79123 | R37: 0 | S37: 254.16614 | T37: 1.83652 | U37: 79.04208 | V37: 2.81508 | W37: 50.39227 | X37: 3.90072 | Y37: 1.52235 | Z37: 67.93534 | AA37: 7.16073 | AB37: 3.44049 | AC37: 4.62484 | AD37: 1.5242 | AE37: 0.2647 | AF37: 0.35934 | AG37: 0.53516 | AH37: 0.45928 | AI37: 0.18861 | AJ37: 0.05829 | AK37: 0.02236 | AL37: 0.00452 | AM37: 0.00077 | AN37: 0.00012 | AO37: 2e-05 | AP37: 0 | AQ37: 0.07448 | AR37: 0.67926 | AS37: 1.10571 | AT37: 0 | AU37: 0 | AV37: 0.80794 | AW37: 0.82167 | AX37: 0.08497 | AY37: 0.01037 | AZ37: 0.00416 | BA37: 0.00355 | BB37: 0.00149 | BC37: 0.00055 | BD37: 0.00018 | BE37: 4e-05 | BF37: 1e-05 | BG37: 0.0022 | BH37: 0.07218 | BI37: 0 | BJ37: 0.0022 | BK37: 0.0377 | BL37: 0.00015 | BM37: 5e-05 | BN37: 0.00068 | BO37: 0 | BP37: 0.00192 | BQ37: 7 | BR37: 6.2748975 | BS37: 2.1218506 | BT37: 2.4562061 | BU37: 5.3158252 | BV37: 6.0109326 | BW37: 6.4596728 | BX37: 6.8028271 | BY37: 7.1811768 | BZ37: 7.9818701 | CA37: 8.3778174 | CB37: 8.6329834 | CC37: 8.8001611 | CD37: 8.9145459 | CE37: 9.0025342 | CF37: 0 | CG37: 2309.339 | CH37: 1938.7482 | CI37: 9.17637 | CJ37: 1.66237 | CK37: 1.34745 | CL37: 12.18619 | CM37: 6.69937 | CN37: 463.09796 | CO37: 0 | CP37: 0 | CQ37: 3.7506 | CR37: 10.11088 | CS37: 0.13749 | CT37: 2.18344 | CU37: 271.16049 | CV37: 1.3544 | CW37: 0 | CX37: 1 | CY37: 0.12721 | CZ37: 0.46476 | DA37: 0.00314 | DB37: 0 | DC37: 0 | DD37: 1 | DE37: 0 | DF37: 0.06119 | DG37: 0.10104 | DH37: 0.00031 | DI37: 0.09891 | DJ37: 0.00033 | DK37: 120.69307 | DL37: 69.42998 | DM37: 15.43834 | DN37: 0.14447 | DO37: 0.04571 | DP37: 0.02169 | DQ37: 0.00117 | DR37: 0 | DS37: 4.43381 | DT37: 6.11447 | DU37: 0.00338 | DV37: 434.99035 | DW37: 0.0027861426 | DX37: 0 | DY37: 2.61018 | DZ37: 0 | EA37: 1.83546 | EB37: 12.84521 | EC37: 0.24382 | ED37: 0 | EE37: 1.85426 | EF37: 0.19051 | EG37: 66.63391 | EH37: 0.08149 | EI37: 0.83025 | EJ37: 194.78327 | EK37: 13.5628 | EL37: 0.01438 | EM37: 0.00208 | EN37: 0.16241 | EO37: 90.32861 | EP37: 0.00608 | EQ37: 0.18601 | ER37: 0.01139 | ES37: 2.27039 | ET37: 0.03698 | EU37: 100 | EV37: 6892.3569 | EW37: Nan | EX37: 0 | EY37: 1.4824
A38: 37 | B38: 0 | C38: 0.90611669 | D38: 281.883 | E38: 7.2448128 | F38: 23.008651 | G38: 25.15504 | H38: 25.544265 | I38: 24.250002 | J38: 23.364142 | K38: 30.83335 | L38: 25.412003 | M38: 21.820016 | N38: 19.853332 | O38: 18.765032 | P38: 18.040037 | Q38: 896.55709 | R38: 0 | S38: 256.04587 | T38: 1.84457 | U38: 80.89383 | V38: 3.14018 | W38: 50.49618 | X38: 4.19723 | Y38: 1.52237 | Z38: 70.56088 | AA38: 7.40374 | AB38: 3.60249 | AC38: 4.62251 | AD38: 2.96551 | AE38: 0.07139 | AF38: 0.36158 | AG38: 0.53593 | AH38: 0.47164 | AI38: 0.19873 | AJ38: 0.06284 | AK38: 0.02478 | AL38: 0.00513 | AM38: 0.0009 | AN38: 0.00014 | AO38: 2e-05 | AP38: 0 | AQ38: 0.07448 | AR38: 0.68128 | AS38: 1.11953 | AT38: 0 | AU38: 0 | AV38: 0.7955 | AW38: 0.80319 | AX38: 0.08196 | AY38: 0.01032 | AZ38: 0.00425 | BA38: 0.00374 | BB38: 0.00159 | BC38: 0.0006 | BD38: 0.0002 | BE38: 5e-05 | BF38: 1e-05 | BG38: 0.0022 | BH38: 0.07218 | BI38: 0 | BJ38: 0.0022 | BK38: 0.03749 | BL38: 0.00017 | BM38: 5e-05 | BN38: 0.00072 | BO38: 0 | BP38: 0.00199 | BQ38: 7 | BR38: 6.2748975 | BS38: 2.1570459 | BT38: 2.4386084 | BU38: 4.9990674 | BV38: 6.0021338 | BW38: 6.4596728 | BX38: 6.7940283 | BY38: 7.1635791 | BZ38: 7.9290772 | CA38: 8.3602197 | CB38: 8.6241846 | CC38: 8.8001611 | CD38: 8.9145459 | CE38: 9.0025342 | CF38: 0 | CG38: 2279.8605 | CH38: 1872.7985 | CI38: 2.68321 | CJ38: 8.29382 | CK38: 0.65641 | CL38: 11.63343 | CM38: 6.69808 | CN38: 472.46969 | CO38: 0 | CP38: 0 | CQ38: 3.76047 | CR38: 9.68432 | CS38: 0.14629 | CT38: 2.12185 | CU38: 156.30947 | CV38: 2.11294 | CW38: 0 | CX38: 1 | CY38: 0.12454 | CZ38: 0.45681 | DA38: 0.00303 | DB38: 0 | DC38: 0 | DD38: 1 | DE38: 0 | DF38: 0.06114 | DG38: 0.09726 | DH38: 0.00034 | DI38: 0.09466 | DJ38: 0.00035 | DK38: 120.66988 | DL38: 70.83504 | DM38: 15.66268 | DN38: 0.1423 | DO38: 0.04652 | DP38: 0.0214 | DQ38: 0.00121 | DR38: 0 | DS38: 4.42111 | DT38: 6.17032 | DU38: 0.00336 | DV38: 460.86634 | DW38: 0.0027943724 | DX38: 0 | DY38: 2.60581 | DZ38: 0 | EA38: 1.65982 | EB38: 12.01511 | EC38: 0.24334 | ED38: 0 | EE38: 1.83592 | EF38: 0.19051 | EG38: 68.56526 | EH38: 0.08427 | EI38: 0.8543 | EJ38: 197.83135 | EK38: 13.48484 | EL38: 0.01438 | EM38: 0.00207 | EN38: 0.1624 | EO38: 90.57218 | EP38: 0.00607 | EQ38: 0.18533 | ER38: 0.0114 | ES38: 2.3159 | ET38: 0.03024 | EU38: 100 | EV38: 7015.8365 | EW38: 0.45499 | EX38: 0 | EY38: 1.56391
A39: 38 | B39: 0 | C39: 0.90611669 | D39: 75.52451 | E39: 14.796835 | F39: 23.554743 | G39: 25.464451 | H39: 25.616197 | I39: 24.214731 | J39: 23.346671 | K39: 31.039432 | L39: 25.626024 | M39: 21.945976 | N39: 19.898811 | O39: 18.767455 | P39: 18.025415 | Q39: 897.32095 | R39: 0 | S39: 257.49991 | T39: 1.84831 | U39: 82.56835 | V39: 3.14899 | W39: 49.46289 | X39: 4.49728 | Y39: 1.52238 | Z39: 73.18572 | AA39: 7.51484 | AB39: 3.67656 | AC39: 4.62461 | AD39: 0.76251 | AE39: 0.14753 | AF39: 0.35833 | AG39: 0.53588 | AH39: 0.48288 | AI39: 0.20866 | AJ39: 0.06747 | AK39: 0.02734 | AL39: 0.0058 | AM39: 0.00104 | AN39: 0.00016 | AO39: 2e-05 | AP39: 0 | AQ39: 0.07448 | AR39: 0.68298 | AS39: 1.12995 | AT39: 0 | AU39: 0 | AV39: 0.78212 | AW39: 0.78031 | AX39: 0.07851 | AY39: 0.01024 | AZ39: 0.00434 | BA39: 0.00393 | BB39: 0.0017 | BC39: 0.00065 | BD39: 0.00022 | BE39: 6e-05 | BF39: 1e-05 | BG39: 0.0022 | BH39: 0.07218 | BI39: 0 | BJ39: 0.0022 | BK39: 0.03723 | BL39: 0.00018 | BM39: 5e-05 | BN39: 0.00076 | BO39: 0 | BP39: 0.00206 | BQ39: 7 | BR39: 6.2748975 | BS39: 2.1658447 | BT39: 2.2274365 | BU39: 5.5006006 | BV39: 5.993335 | BW39: 6.4596728 | BX39: 6.7940283 | BY39: 7.1459814 | BZ39: 7.8762842 | CA39: 8.3426221 | CB39: 8.6241846 | CC39: 8.8001611 | CD39: 8.9145459 | CE39: 9.0025342 | CF39: 0 | CG39: 2272.3673 | CH39: 2141.6834 | CI39: 1.30358 | CJ39: 7.93952 | CK39: 1.90562 | CL39: 11.14873 | CM39: 6.68652 | CN39: 479.49964 | CO39: 0 | CP39: 0 | CQ39: 3.75968 | CR39: 9.27804 | CS39: 0.08323 | CT39: 2.11305 | CU39: 366.58506 | CV39: 0.33939 | CW39: 0 | CX39: 1 | CY39: 0.12128 | CZ39: 0.44719 | DA39: 0.00289 | DB39: 0 | DC39: 0 | DD39: 1 | DE39: 0 | DF39: 0.0611 | DG39: 0.09278 | DH39: 0.00036 | DI39: 0.0914 | DJ39: 0.00037 | DK39: 120.46153 | DL39: 71.889 | DM39: 15.81933 | DN39: 0.14016 | DO39: 0.04722 | DP39: 0.02108 | DQ39: 0.00124 | DR39: 20.27422 | DS39: 4.40081 | DT39: 6.22025 | DU39: 0.00334 | DV39: 472.82669 | DW39: 0.0028025946 | DX39: 0 | DY39: 2.59579 | DZ39: 0 | EA39: 1.52425 | EB39: 11.23865 | EC39: 0.24276 | ED39: 0 | EE39: 2.03392 | EF39: 0.19051 | EG39: 70.49256 | EH39: 0.08704 | EI39: 0.87837 | EJ39: 200.87943 | EK39: 13.40818 | EL39: 0.01437 | EM39: 0.00206 | EN39: 0.16228 | EO39: 90.81522 | EP39: 0.00607 | EQ39: 0.18466 | ER39: 0.01141 | ES39: 2.36787 | ET39: 0.02473 | EU39: 100 | EV39: 7134.3192 | EW39: 0.41708 | EX39: 0 | EY39: 1.57278
A40: 39 | B40: 0 | C40: 0.90611669 | D40: 150.25075 | E40: 26.648907 | F40: 23.472389 | G40: 25.837978 | H40: 25.725717 | I40: 24.189906 | J40: 23.326939 | K40: 31.234072 | L40: 25.838444 | M40: 22.075873 | N40: 19.948155 | O40: 18.771999 | P40: 18.011657 | Q40: 898.08304 | R40: 0 | S40: 258.43313 | T40: 1.84778 | U40: 84.06088 | V40: 2.74351 | W40: 49.51017 | X40: 4.79964 | Y40: 1.5224 | Z40: 75.80706 | AA40: 7.44662 | AB40: 3.63108 | AC40: 4.63045 | AD40: 1.50036 | AE40: 0.25875 | AF40: 0.34866 | AG40: 0.53536 | AH40: 0.49297 | AI40: 0.21835 | AJ40: 0.07217 | AK40: 0.03004 | AL40: 0.00653 | AM40: 0.00119 | AN40: 0.00019 | AO40: 3e-05 | AP40: 0 | AQ40: 0.07448 | AR40: 0.68435 | AS40: 1.13713 | AT40: 0 | AU40: 0 | AV40: 0.7685 | AW40: 0.75372 | AX40: 0.07483 | AY40: 0.01016 | AZ40: 0.00442 | BA40: 0.00412 | BB40: 0.00181 | BC40: 0.0007 | BD40: 0.00025 | BE40: 7e-05 | BF40: 2e-05 | BG40: 0.0022 | BH40: 0.07218 | BI40: 0 | BJ40: 0.0022 | BK40: 0.03693 | BL40: 0.0002 | BM40: 5e-05 | BN40: 0.0008 | BO40: 0 | BP40: 0.00214 | BQ40: 7 | BR40: 6.2748975 | BS40: 2.1130518 | BT40: 2.4386084 | BU40: 5.1662451 | BV40: 5.9757373 | BW40: 6.4596728 | BX40: 6.7940283 | BY40: 7.1371826 | BZ40: 7.8234912 | CA40: 8.3338232 | CB40: 8.6153857 | CC40: 8.8001611 | CD40: 8.9145459 | CE40: 9.0025342 | CF40: 0 | CG40: 2329.2825 | CH40: 1977.627 | CI40: 8.01373 | CJ40: 1.44937 | CK40: 1.17594 | CL40: 10.63904 | CM40: 6.66479 | CN40: 484.03409 | CO40: 0 | CP40: 0 | CQ40: 3.7526 | CR40: 8.93296 | CS40: 0.16389 | CT40: 2.16584 | CU40: 290.18621 | CV40: 0.44691 | CW40: 0 | CX40: 1 | CY40: 0.11755 | CZ40: 0.43626 | DA40: 0.00275 | DB40: 0 | DC40: 0 | DD40: 1 | DE40: 0 | DF40: 0.06106 | DG40: 0.08919 | DH40: 0.00038 | DI40: 0.08707 | DJ40: 0.0004 | DK40: 120.07005 | DL40: 72.56883 | DM40: 15.90434 | DN40: 0.13875 | DO40: 0.04781 | DP40: 0.02075 | DQ40: 0.00128 | DR40: 0 | DS40: 4.3731 | DT40: 6.26384 | DU40: 0.00331 | DV40: 465.65404 | DW40: 0.0028107967 | DX40: 0 | DY40: 2.58702 | DZ40: 0 | EA40: 1.42364 | EB40: 10.51238 | EC40: 0.24207 | ED40: 0 | EE40: 1.8573 | EF40: 0.19051 | EG40: 72.40553 | EH40: 0.08981 | EI40: 0.90246 | EJ40: 203.92751 | EK40: 13.33291 | EL40: 0.01437 | EM40: 0.00204 | EN40: 0.16204 | EO40: 91.05762 | EP40: 0.00607 | EQ40: 0.18399 | ER40: 0.01141 | ES40: 2.41939 | ET40: 0.02022 | EU40: 100 | EV40: 7248.0176 | EW40: 0.44003 | EX40: 0 | EY40: 1.57992
A41: 40 | B41: 0 | C41: 0.90611669 | D41: 301.10508 | E41: 7.5897442 | F41: 24.724628 | G41: 26.250171 | H41: 25.875698 | I41: 24.178073 | J41: 23.306145 | K41: 31.417473 | L41: 26.048799 | M41: 22.209435 | N41: 20.001367 | O41: 18.778752 | P41: 17.998829 | Q41: 898.84355 | R41: 0 | S41: 260.78937 | T41: 1.84306 | U41: 85.36785 | V41: 3.08156 | W41: 49.54361 | X41: 5.10312 | Y41: 1.52242 | Z41: 78.42237 | AA41: 7.70407 | AB41: 3.80271 | AC41: 4.638 | AD41: 2.91478 | AE41: 0.06969 | AF41: 0.35193 | AG41: 0.53436 | AH41: 0.50192 | AI41: 0.22776 | AJ41: 0.07692 | AK41: 0.03287 | AL41: 0.00731 | AM41: 0.00137 | AN41: 0.00022 | AO41: 3e-05 | AP41: 0 | AQ41: 0.07448 | AR41: 0.68543 | AS41: 1.14133 | AT41: 0 | AU41: 0 | AV41: 0.75429 | AW41: 0.72421 | AX41: 0.07109 | AY41: 0.01007 | AZ41: 0.0045 | BA41: 0.00431 | BB41: 0.00191 | BC41: 0.00075 | BD41: 0.00027 | BE41: 8e-05 | BF41: 2e-05 | BG41: 0.0022 | BH41: 0.07218 | BI41: 0 | BJ41: 0.0022 | BK41: 0.0366 | BL41: 0.00022 | BM41: 5e-05 | BN41: 0.00084 | BO41: 0 | BP41: 0.00221 | BQ41: 7 | BR41: 6.2748975 | BS41: 2.1482471 | BT41: 2.4298096 | BU41: 4.9286768 | BV41: 5.9669385 | BW41: 6.4596728 | BX41: 6.7940283 | BY41: 7.1283838 | BZ41: 7.7794971 | CA41: 8.3162256 | CB41: 8.6065869 | CC41: 8.7913623 | CD41: 8.9233447 | CE41: 9.011333 | CF41: 0 | CG41: 2299.8787 | CH41: 1916.2391 | CI41: 2.35032 | CJ41: 7.22593 | CK41: 0.57387 | CL41: 10.15012 | CM41: 6.63317 | CN41: 485.98836 | CO41: 0 | CP41: 0 | CQ41: 3.73361 | CR41: 8.47272 | CS41: 0.16976 | CT41: 2.11305 | CU41: 166.98469 | CV41: 0.38061 | CW41: 0 | CX41: 1 | CY41: 0.11349 | CZ41: 0.42441 | DA41: 0.0026 | DB41: 0 | DC41: 0 | DD41: 1 | DE41: 0 | DF41: 0.06102 | DG41: 0.08528 | DH41: 0.00041 | DI41: 0.08278 | DJ41: 0.00042 | DK41: 119.5005 | DL41: 72.86182 | DM41: 15.97614 | DN41: 0.13667 | DO41: 0.0483 | DP41: 0.02041 | DQ41: 0.00131 | DR41: 0 | DS41: 4.33828 | DT41: 6.30075 | DU41: 0.00328 | DV41: 492.3599 | DW41: 0.0028189663 | DX41: 0 | DY41: 2.57751 | DZ41: 0 | EA41: 1.35399 | EB41: 9.83303 | EC41: 0.24127 | ED41: 0 | EE41: 1.84498 | EF41: 0.19051 | EG41: 74.34117 | EH41: 0.09257 | EI41: 0.92655 | EJ41: 206.97559 | EK41: 13.25913 | EL41: 0.01436 | EM41: 0.00202 | EN41: 0.16169 | EO41: 91.29927 | EP41: 0.00607 | EQ41: 0.18333 | ER41: 0.01142 | ES41: 2.47216 | ET41: 0.01653 | EU41: 100 | EV41: 7357.1457 | EW41: 0.44366 | EX41: 0 | EY41: 1.58571
A42: 41 | B42: 0 | C42: 0.90611669 | D42: 80.391755 | E42: 15.557086 | F42: 25.433994 | G42: 26.709012 | H42: 26.068687 | I42: 24.181727 | J42: 23.285594 | K42: 31.589948 | L42: 26.256657 | M42: 22.346381 | N42: 20.058436 | O42: 18.787797 | P42: 17.986998 | Q42: 899.60268 | R42: 0 | S42: 262.70523 | T42: 1.83424 | U42: 86.48717 | V42: 3.10703 | W42: 48.48392 | X42: 5.4066 | Y42: 1.52244 | Z42: 81.02946 | AA42: 7.82033 | AB42: 3.88022 | AC42: 4.64868 | AD42: 0.74877 | AE42: 0.14369 | AF42: 0.34976 | AG42: 0.53286 | AH42: 0.50973 | AI42: 0.23685 | AJ42: 0.0817 | AK42: 0.03583 | AL42: 0.00816 | AM42: 0.00156 | AN42: 0.00026 | AO42: 4e-05 | AP42: 1e-05 | AQ42: 0.07448 | AR42: 0.68623 | AS42: 1.1429 | AT42: 0 | AU42: 0 | AV42: 0.73986 | AW42: 0.69267 | AX42: 0.06745 | AY42: 0.00999 | AZ42: 0.00457 | BA42: 0.00449 | BB42: 0.00202 | BC42: 0.0008 | BD42: 0.0003 | BE42: 9e-05 | BF42: 2e-05 | BG42: 0.0022 | BH42: 0.07218 | BI42: 0 | BJ42: 0.0022 | BK42: 0.03623 | BL42: 0.00023 | BM42: 5e-05 | BN42: 0.00087 | BO42: 0 | BP42: 0.00228 | BQ42: 7 | BR42: 6.2748975 | BS42: 2.1570459 | BT42: 2.2186377 | BU42: 5.3598193 | BV42: 5.9493408 | BW42: 6.4596728 | BX42: 6.7940283 | BY42: 7.119585 | BZ42: 7.7355029 | CA42: 8.2986279 | CB42: 8.5977881 | CC42: 8.7913623 | CD42: 8.9233447 | CE42: 9.011333 | CF42: 0 | CG42: 2292.8045 | CH42: 2173.3248 | CI42: 1.151 | CJ42: 6.91491 | CK42: 1.65658 | CL42: 9.72249 | CM42: 6.59211 | CN42: 485.35197 | CO42: 0 | CP42: 0 | CQ42: 3.70625 | CR42: 8.05695 | CS42: 0.1067 | CT42: 2.11305 | CU42: 390.62136 | CV42: 0 | CW42: 0 | CX42: 1 | CY42: 0.10923 | CZ42: 0.41207 | DA42: 0.00244 | DB42: 0 | DC42: 0 | DD42: 1 | DE42: 0 | DF42: 0.06099 | DG42: 0.08057 | DH42: 0.00043 | DI42: 0.07927 | DJ42: 0.00045 | DK42: 118.76081 | DL42: 72.76641 | DM42: 16.00057 | DN42: 0.13461 | DO42: 0.04868 | DP42: 0.02005 | DQ42: 0.00135 | DR42: 21.97225 | DS42: 4.29674 | DT42: 6.33068 | DU42: 0.00325 | DV42: 503.82788 | DW42: 0.0028270915 | DX42: 0 | DY42: 2.56332 | DZ42: 0 | EA42: 1.31223 | EB42: 9.19759 | EC42: 0.24038 | ED42: 0 | EE42: 2.03657 | EF42: 0.19051 | EG42: 76.27328 | EH42: 0.09532 | EI42: 0.95066 | EJ42: 210.02367 | EK42: 13.18693 | EL42: 0.01436 | EM42: 0.00199 | EN42: 0.16123 | EO42: 91.54008 | EP42: 0.00607 | EQ42: 0.18267 | ER42: 0.01142 | ES42: 2.52749 | ET42: 0.01352 | EU42: 100 | EV42: 7461.9192 | EW42: 0.40782 | EX42: 0 | EY42: 1.58999
A43: 42 | B43: 0 | C43: 0.90611669 | D43: 159.96756 | E43: 28.048189 | F43: 25.456042 | G43: 27.243478 | H43: 26.306559 | I43: 24.203303 | J43: 23.26669 | K43: 31.751918 | L43: 26.461628 | M43: 22.486424 | N43: 20.11934 | O43: 18.799211 | P43: 17.976231 | Q43: 900.36061 | R43: 0 | S43: 264.07082 | T43: 1.82147 | U43: 87.41823 | V43: 2.71835 | W43: 48.52066 | X43: 5.70903 | Y43: 1.52247 | Z43: 83.62664 | AA43: 7.74654 | AB43: 3.83103 | AC43: 4.66175 | AD43: 1.47342 | AE43: 0.25253 | AF43: 0.34121 | AG43: 0.5312 | AH43: 0.51645 | AI43: 0.2456 | AJ43: 0.08648 | AK43: 0.0389 | AL43: 0.00906 | AM43: 0.00176 | AN43: 0.0003 | AO43: 5e-05 | AP43: 1e-05 | AQ43: 0.07448 | AR43: 0.68677 | AS43: 1.14222 | AT43: 0 | AU43: 0 | AV43: 0.72602 | AW43: 0.65998 | AX43: 0.06403 | AY43: 0.00991 | AZ43: 0.00464 | BA43: 0.00467 | BB43: 0.00213 | BC43: 0.00086 | BD43: 0.00032 | BE43: 0.0001 | BF43: 3e-05 | BG43: 0.0022 | BH43: 0.07219 | BI43: 0 | BJ43: 0.0022 | BK43: 0.03585 | BL43: 0.00025 | BM43: 5e-05 | BN43: 0.00091 | BO43: 0 | BP43: 0.00235 | BQ43: 7 | BR43: 6.2748975 | BS43: 2.1042529 | BT43: 2.4210107 | BU43: 4.9990674 | BV43: 5.9317432 | BW43: 6.450874 | BX43: 6.7940283 | BY43: 7.1107861 | BZ43: 7.6915088 | CA43: 8.2810303 | CB43: 8.5889893 | CC43: 8.7913623 | CD43: 8.9233447 | CE43: 9.011333 | CF43: 0 | CG43: 2347.8695 | CH43: 2013.0711 | CI43: 6.98429 | CJ43: 1.26079 | CK43: 1.02638 | CL43: 9.27146 | CM43: 6.5422 | CN43: 482.18868 | CO43: 0 | CP43: 0 | CQ43: 3.67943 | CR43: 7.7173 | CS43: 0.17709 | CT43: 2.15705 | CU43: 308.45602 | CV43: 0 | CW43: 0 | CX43: 1 | CY43: 0.10491 | CZ43: 0.39964 | DA43: 0.0023 | DB43: 0 | DC43: 0 | DD43: 1 | DE43: 0 | DF43: 0.06096 | DG43: 0.07705 | DH43: 0.00045 | DI43: 0.07516 | DJ43: 0.00047 | DK43: 117.86155 | DL43: 72.29216 | DM43: 15.99502 | DN43: 0.13325 | DO43: 0.04896 | DP43: 0.01968 | DQ43: 0.00138 | DR43: 0 | DS43: 4.24898 | DT43: 6.35343 | DU43: 0.00322 | DV43: 495.09972 | DW43: 0.0028351609 | DX43: 0 | DY43: 2.55197 | DZ43: 0 | EA43: 1.29616 | EB43: 8.60321 | EC43: 0.23939 | ED43: 0 | EE43: 1.86037 | EF43: 0.19051 | EG43: 78.19083 | EH43: 0.09806 | EI43: 0.97479 | EJ43: 213.07175 | EK43: 13.11638 | EL43: 0.01435 | EM43: 0.00196 | EN43: 0.16066 | EO43: 91.77994 | EP43: 0.00607 | EQ43: 0.18203 | ER43: 0.01142 | ES43: 2.58198 | ET43: 0.01105 | EU43: 100 | EV43: 7562.5545 | EW43: 0.42925 | EX43: 0 | EY43: 1.59232
A44: 43 | B44: 0 | C44: 0.90611669 | D44: 319.4963 | E44: 7.943339 | F44: 26.928539 | G44: 27.824692 | H44: 26.591118 | I44: 24.245173 | J44: 23.250921 | K44: 31.903919 | L44: 26.663363 | M44: 22.629272 | N44: 20.184044 | O44: 18.813069 | P44: 17.966596 | Q44: 901.11753 | R44: 0 | S44: 267.00071 | T44: 1.80491 | U44: 88.16196 | V44: 3.0667 | W44: 48.56905 | X44: 6.00947 | Y44: 1.52251 | Z44: 86.21245 | AA44: 8.02009 | AB44: 4.01339 | AC44: 4.6751 | AD44: 2.85766 | AE44: 0.06808 | AF44: 0.34579 | AG44: 0.52935 | AH44: 0.52216 | AI44: 0.25398 | AJ44: 0.09126 | AK44: 0.04209 | AL44: 0.01003 | AM44: 0.00199 | AN44: 0.00034 | AO44: 5e-05 | AP44: 1e-05 | AQ44: 0.07448 | AR44: 0.68706 | AS44: 1.13973 | AT44: 0 | AU44: 0 | AV44: 0.71221 | AW44: 0.62691 | AX44: 0.0609 | AY44: 0.00985 | AZ44: 0.0047 | BA44: 0.00485 | BB44: 0.00224 | BC44: 0.00091 | BD44: 0.00035 | BE44: 0.00012 | BF44: 3e-05 | BG44: 0.00221 | BH44: 0.07219 | BI44: 0 | BJ44: 0.00221 | BK44: 0.03546 | BL44: 0.00026 | BM44: 5e-05 | BN44: 0.00095 | BO44: 0 | BP44: 0.00242 | BQ44: 7 | BR44: 6.2748975 | BS44: 2.1394482 | BT44: 2.4122119 | BU44: 4.8494873 | BV44: 5.9053467 | BW44: 6.450874 | BX44: 6.7940283 | BY44: 7.1107861 | BZ44: 7.6563135 | CA44: 8.2546338 | CB44: 8.5801904 | CC44: 8.7913623 | CD44: 8.9233447 | CE44: 9.011333 | CF44: 0 | CG44: 2318.3162 | CH44: 1961.5269 | CI44: 2.05564 | CJ44: 6.28055 | CK44: 0.50265 | CL44: 8.83884 | CM44: 6.48413 | CN44: 476.63161 | CO44: 0 | CP44: 0 | CQ44: 3.63428 | CR44: 7.28287 | CS44: 0.18295 | CT44: 2.11305 | CU44: 177.23084 | CV44: 0.02022 | CW44: 0 | CX44: 1 | CY44: 0.10063 | CZ44: 0.38746 | DA44: 0.00216 | DB44: 0 | DC44: 0 | DD44: 1 | DE44: 0 | DF44: 0.06093 | DG44: 0.07337 | DH44: 0.00048 | DI44: 0.07124 | DJ44: 0.0005 | DK44: 116.8155 | DL44: 71.45901 | DM44: 15.95902 | DN44: 0.13122 | DO44: 0.04914 | DP44: 0.0193 | DQ44: 0.00141 | DR44: 0 | DS44: 4.19557 | DT44: 6.36886 | DU44: 0.00318 | DV44: 522.55013 | DW44: 0.0028431642 | DX44: 0 | DY44: 2.54115 | DZ44: 0 | EA44: 1.30437 | EB44: 8.04725 | EC44: 0.23831 | ED44: 0 | EE44: 1.85018 | EF44: 0.19051 | EG44: 80.13136 | EH44: 0.10078 | EI44: 0.99893 | EJ44: 216.11983 | EK44: 13.04756 | EL44: 0.01434 | EM44: 0.00192 | EN44: 0.16 | EO44: 92.01876 | EP44: 0.00606 | EQ44: 0.18139 | ER44: 0.01141 | ES44: 2.6383 | ET44: 0.00904 | EU44: 100 | EV44: 7659.2661 | EW44: 0.43122 | EX44: 0 | EY44: 1.59314
A45: 44 | B45: 0 | C45: 0.90611669 | D45: 85.01861 | E45: 16.297149 | F45: 27.79586 | G45: 28.459841 | H45: 26.923928 | I45: 24.309628 | J45: 23.23985 | K45: 32.046596 | L45: 26.861561 | M45: 22.774632 | N45: 20.252501 | O45: 18.829437 | P45: 17.958159 | Q45: 901.87362 | R45: 0 | S45: 269.45199 | T45: 1.78479 | U45: 88.72082 | V45: 3.10042 | W45: 47.54375 | X45: 6.30706 | Y45: 1.52255 | Z45: 88.78567 | AA45: 8.14372 | AB45: 4.09581 | AC45: 4.69053 | AD45: 0.73321 | AE45: 0.13985 | AF45: 0.34478 | AG45: 0.52726 | AH45: 0.52686 | AI45: 0.26198 | AJ45: 0.09603 | AK45: 0.04539 | AL45: 0.01106 | AM45: 0.00224 | AN45: 0.0004 | AO45: 6e-05 | AP45: 1e-05 | AQ45: 0.07448 | AR45: 0.68713 | AS45: 1.13581 | AT45: 0 | AU45: 0 | AV45: 0.69874 | AW45: 0.59427 | AX45: 0.0581 | AY45: 0.00981 | AZ45: 0.00476 | BA45: 0.00502 | BB45: 0.00236 | BC45: 0.00097 | BD45: 0.00037 | BE45: 0.00013 | BF45: 4e-05 | BG45: 0.00221 | BH45: 0.07219 | BI45: 0 | BJ45: 0.00221 | BK45: 0.03506 | BL45: 0.00027 | BM45: 5e-05 | BN45: 0.00098 | BO45: 0 | BP45: 0.00248 | BQ45: 7 | BR45: 6.2748975 | BS45: 2.1570459 | BT45: 2.2098389 | BU45: 5.1574463 | BV45: 5.887749 | BW45: 6.450874 | BX45: 6.7940283 | BY45: 7.1019873 | BZ45: 7.6211182 | CA45: 8.2370361 | CB45: 8.5713916 | CC45: 8.7913623 | CD45: 8.9233447 | CE45: 9.011333 | CF45: 0 | CG45: 2303.8584 | CH45: 2201.388 | CI45: 1.0153 | CJ45: 6.00826 | CK45: 1.43843 | CL45: 8.46199 | CM45: 6.41873 | CN45: 468.87405 | CO45: 0 | CP45: 0 | CQ45: 3.58371 | CR45: 6.9078 | CS45: 0.14043 | CT45: 2.10425 | CU45: 413.63541 | CV45: 0 | CW45: 0 | CX45: 1 | CY45: 0.0965 | CZ45: 0.37584 | DA45: 0.00203 | DB45: 0 | DC45: 0 | DD45: 1 | DE45: 0 | DF45: 0.06091 | DG45: 0.06908 | DH45: 0.0005 | DI45: 0.068 | DJ45: 0.00052 | DK45: 115.63721 | DL45: 70.29596 | DM45: 15.9014 | DN45: 0.12921 | DO45: 0.04923 | DP45: 0.01892 | DQ45: 0.00144 | DR45: 23.92417 | DS45: 4.13712 | DT45: 6.37694 | DU45: 0.00315 | DV45: 533.48546 | DW45: 0.0028510917 | DX45: 0 | DY45: 2.52632 | DZ45: 0 | EA45: 1.33615 | EB45: 7.52721 | EC45: 0.23714 | ED45: 0 | EE45: 2.0385 | EF45: 0.19051 | EG45: 82.06812 | EH45: 0.10349 | EI45: 1.02307 | EJ45: 219.16791 | EK45: 12.98054 | EL45: 0.01433 | EM45: 0.00188 | EN45: 0.15923 | EO45: 92.25645 | EP45: 0.00606 | EQ45: 0.18075 | ER45: 0.01141 | ES45: 2.69899 | ET45: 0.00739 | EU45: 100 | EV45: 7752.2643 | EW45: 0.39718 | EX45: 0 | EY45: 1.5924
A46: 45 | B46: 0 | C46: 0.09415703 | D46: 167.8393 | E46: 29.196253 | F46: 27.902273 | G46: 29.178789 | H46: 27.30597 | I46: 24.398889 | J46: 23.235096 | K46: 32.180706 | L46: 27.05597 | M46: 22.922209 | N46: 20.324654 | O46: 18.84838 | P46: 17.950988 | Q46: 902.62904 | R46: 0 | S46: 271.30393 | T46: 1.76136 | U46: 89.09883 | V46: 2.71811 | W46: 47.62924 | X46: 6.60108 | Y46: 1.5226 | Z46: 91.34544 | AA46: 8.03807 | AB46: 4.02538 | AC46: 4.70745 | AD46: 1.44318 | AE46: 0.24602 | AF46: 0.33725 | AG46: 0.52521 | AH46: 0.53065 | AI46: 0.26958 | AJ46: 0.10075 | AK46: 0.04878 | AL46: 0.01215 | AM46: 0.00252 | AN46: 0.00045 | AO46: 7e-05 | AP46: 1e-05 | AQ46: 0.07448 | AR46: 0.687 | AS46: 1.13085 | AT46: 0 | AU46: 0 | AV46: 0.68641 | AW46: 0.56271 | AX46: 0.05564 | AY46: 0.00978 | AZ46: 0.00482 | BA46: 0.00519 | BB46: 0.00247 | BC46: 0.00102 | BD46: 0.0004 | BE46: 0.00014 | BF46: 4e-05 | BG46: 0.00221 | BH46: 0.07219 | BI46: 0 | BJ46: 0.00221 | BK46: 0.03467 | BL46: 0.00027 | BM46: 5e-05 | BN46: 0.00101 | BO46: 0 | BP46: 0.00255 | BQ46: 7 | BR46: 6.4332764 | BS46: 2.0954541 | BT46: 2.4122119 | BU46: 4.9110791 | BV46: 5.8613525 | BW46: 6.4420752 | BX46: 6.7940283 | BY46: 7.1019873 | BZ46: 7.5859229 | CA46: 8.2194385 | CB46: 8.5625928 | CC46: 8.7825635 | CD46: 8.9233447 | CE46: 9.0201318 | CF46: 0 | CG46: 2384.8727 | CH46: 2051.4815 | CI46: 5.94659 | CJ46: 1.09402 | CK46: 0.89224 | CL46: 7.93285 | CM46: 6.34686 | CN46: 459.15721 | CO46: 0 | CP46: 0 | CQ46: 3.54033 | CR46: 6.60824 | CS46: 0.19175 | CT46: 2.14825 | CU46: 323.85516 | CV46: 0 | CW46: 0 | CX46: 1 | CY46: 0.0926 | CZ46: 0.36499 | DA46: 0.00192 | DB46: 0 | DC46: 0 | DD46: 1 | DE46: 0 | DF46: 0.06089 | DG46: 0.06603 | DH46: 0.00053 | DI46: 0.06449 | DJ46: 0.00055 | DK46: 114.34244 | DL46: 68.83916 | DM46: 15.84582 | DN46: 0.12787 | DO46: 0.04924 | DP46: 0.01854 | DQ46: 0.00147 | DR46: 0 | DS46: 4.07431 | DT46: 6.37771 | DU46: 0.00311 | DV46: 520.30352 | DW46: 0.0028589349 | DX46: 0 | DY46: 2.51557 | DZ46: 0 | EA46: 1.39136 | EB46: 7.04077 | EC46: 0.23589 | ED46: 0 | EE46: 1.866 | EF46: 0.08474 | EG46: 83.99097 | EH46: 0.10619 | EI46: 1.04723 | EJ46: 221.58228 | EK46: 12.9154 | EL46: 0.01432 | EM46: 0.00183 | EN46: 0.15837 | EO46: 92.49294 | EP46: 0.00606 | EQ46: 0.18013 | ER46: 0.0114 | ES46: 2.76006 | ET46: 0.00604 | EU46: 100 | EV46: 7841.7524 | EW46: 0.41729 | EX46: 0 | EY46: 1.58978
