Workbook
Name _1_water: arabinose!$B$1
Name _1_water: 'rapid starch'!$B$1
Name _1_water: 'resistant starch'!$B$1
Name _1_water: 'slow starch'!$B$1
Name _1_water: sucrose!$B$1
Name milk_choc: meal!$G$13

Sheet meal
A1: Inlezen maaltijden
A2: reference time (minutes after midnight corresponding with time = 0 | D2: (min) | E2: 500
A4: time | B4: compound | C4: amount | D4: dish | E4: eating speed
A5: (min) | B5: (number) | C5: (g) | D5: (number) | E5: (ml/min)
A6: 0 | B6: 29 | C6: 300 | D6: 1 | E6: 64
A7: 1 | B7: 28 | C7: 0 | D7: 1 | E7: 64
A8: 2 | B8: 26 | C8: 0 | D8: 1 | E8: 64
A9: 1000 | B9: 1 | C9: 0 | D9: 1 | E9: 64
A10: 9999
A12: compound number | C12: (number) | D12: 1 | E12: 2 | F12: 3 | G12: 4 | H12: 5 | I12: 6 | J12: 7 | K12: 8 | L12: 9 | M12: 10 | N12: 11 | O12: 12 | P12: 13 | Q12: 14 | R12: 15 | S12: 16 | T12: 17 | U12: 18 | V12: 19 | W12: 20 | X12: 21 | Y12: 22 | Z12: 23 | AA12: 24 | AB12: 25 | AC12: 26 | AD12: 27 | AE12: 28 | AF12: 29 | AG12: 9999
A13: Compound quantifiers | D13: water | E13: glucose | F13: sucrose | G13: milk choc | H13: milk choc arab | I13: gastic milk choc'!A1 | J13: gastic milk choc arab'!A1 | K13: emulsie | L13: arabinose | M13: Rapid starch | N13: Slow starch | O13: resistant starch | P13: extruded | Q13: biscuit | R13: bread meal Eelderink | S13: bread masticated | T13: bread dispersed | U13: pasta Eelderink 2012 | V13: pasta masticated | W13: pasta dispersed | X13: water | Y13: water | Z13: water | AA13: water | AB13: BLG | AC13: comp pepsin inh | AD13: non comp pepsin inh | AE13: comp pancr inh | AF13: BLG
A14: pH | C14: (-) | D14: =water!D4 -> 7 | E14: =glucose!D4 -> 7 | F14: =sucrose!D4 -> 7 | G14: ='milk choc'!D4 -> 7 | H14: ='milk chocolate arabinose'!D4 -> 7 | I14: ='gastic milk choc'!D4 -> 7 | J14: ='gastic milk choc arab'!D4 -> 7 | K14: =emulsie!D4 -> 7 | L14: =arabinose!D4 -> 7 | M14: 7 | N14: 7 | O14: 7 | P14: 7 | Q14: 7 | R14: 7 | S14: 7 | T14: 7 | U14: 7 | V14: 7 | W14: 7 | X14: 0 | Y14: 0 | Z14: 0 | AA14: 0 | AB14: 7 | AC14: 7 | AD14: 7 | AE14: 7 | AF14: 7
A15: solid | C15: particlesize (mm) | D15: =water!D5 -> 0 | E15: 1 | F15: 1 | G15: ='milk choc'!D5 -> 1 | H15: ='milk chocolate arabinose'!D5 -> 1 | I15: 0 | J15: 0 | K15: =emulsie!D5 -> 0 | L15: =arabinose!D5 -> 1 | M15: 2 | N15: 1 | O15: 1 | P15: 1 | Q15: 1 | R15: 20 | S15: 5 | T15: 1 | U15: 20 | V15: 5 | W15: 1 | X15: 0 | Y15: 0 | Z15: 0 | AA15: 0 | AB15: 1 | AC15: 0 | AD15: 0 | AE15: 0 | AF15: 1
A16: viscosity | C16: (mPa.s) | D16: =water!D6 -> 1 | E16: =glucose!D6 -> 1 | F16: =sucrose!D6 -> 1 | G16: ='milk choc'!D6 -> 1 | H16: ='milk chocolate arabinose'!D6 -> 1 | I16: 1000 | J16: 1000 | K16: =emulsie!D6 -> 1 | L16: =arabinose!D6 -> 1 | M16: 1000 | N16: 1 | O16: 1 | P16: 10000 | Q16: 10000 | R16: 1000 | S16: 10 | T16: 10 | U16: 1000 | V16: 10 | W16: 10 | X16: 0 | Y16: 0 | Z16: 0 | AA16: 0 | AB16: 1 | AC16: 0 | AD16: 0 | AE16: 0 | AF16: 1
A17: oral decomposition time | C17: (min) | D17: 0.1 | E17: 0.1 | F17: 0.1 | G17: 1 | H17: 1 | I17: 5 | J17: 5 | K17: =emulsie!D7 -> 1 | L17: 0.1 | M17: 10 | N17: 50 | O17: 1 | P17: 10 | Q17: 20 | R17: 0.5 | S17: 50 | T17: 50 | U17: 0.5 | V17: 50 | W17: 50 | X17: 0.1 | Y17: 0.1 | Z17: 0.1 | AA17: 0.1 | AB17: 0.1 | AC17: 0.1 | AD17: 0.1 | AE17: 0.1 | AF17: 0.1
C18: decomposes into (compound) | D18: =water!D8 -> 0 | E18: =glucose!D8 -> 0 | F18: =sucrose!D8 -> 0 | G18: ='milk choc'!D8 -> 6 | H18: 7 | I18: ='gastic milk choc'!D8 -> 0 | J18: ='gastic milk choc arab'!D8 -> 0 | K18: =emulsie!D8 -> 0 | L18: =arabinose!D8 -> 0 | M18: 0 | N18: 0 | O18: 0 | P18: 10 | Q18: 11 | R18: 16 | S18: 17 | T18: 0 | U18: 19 | V18: 20 | W18: 0 | X18: 0 | Y18: 0 | Z18: 0 | AA18: 0 | AB18: 0 | AC18: 0 | AD18: 0 | AE18: 0 | AF18: 0
C19: (%) | D19: =water!D9 -> 0 | E19: =glucose!D9 -> 0 | F19: =sucrose!D9 -> 0 | G19: 95 | H19: 95 | I19: ='gastic milk choc'!D9 -> 0 | J19: ='gastic milk choc arab'!D9 -> 0 | K19: =emulsie!D9 -> 0 | L19: =arabinose!D9 -> 0 | M19: 0 | N19: 0 | O19: 0 | P19: 50 | Q19: 100 | R19: 60 | S19: 100 | T19: 0 | U19: 70 | V19: 100 | W19: 0 | X19: 0 | Y19: 0 | Z19: 0 | AA19: 0 | AB19: 0 | AC19: 0 | AD19: 0 | AE19: 0 | AF19: 0
C20: and (compound) | D20: =water!D10 -> 0 | E20: =glucose!D10 -> 0 | F20: =sucrose!D10 -> 0 | G20: ='milk choc'!D10 -> 0 | H20: ='milk chocolate arabinose'!D10 -> 0 | I20: ='gastic milk choc'!D10 -> 0 | J20: ='gastic milk choc arab'!D10 -> 0 | K20: =emulsie!D10 -> 0 | L20: =arabinose!D10 -> 0 | M20: 0 | N20: 0 | O20: 0 | P20: 0 | Q20: 0 | R20: 0 | S20: 0 | T20: 0 | U20: 0 | V20: 0 | W20: 0 | X20: 0 | Y20: 0 | Z20: 0 | AA20: 0 | AB20: 0 | AC20: 0 | AD20: 0 | AE20: 0 | AF20: 0
C21: (%) | D21: =water!D11 -> 0 | E21: =glucose!D11 -> 0 | F21: =sucrose!D11 -> 0 | G21: ='milk choc'!D11 -> 0 | H21: ='milk chocolate arabinose'!D11 -> 0 | I21: ='gastic milk choc'!D11 -> 0 | J21: ='gastic milk choc arab'!D11 -> 0 | K21: =emulsie!D11 -> 0 | L21: =arabinose!D11 -> 0 | M21: 0 | N21: 0 | O21: 0 | P21: 0 | Q21: 0 | R21: 0 | S21: 0 | T21: 0 | U21: 0 | V21: 0 | W21: 0 | X21: 0 | Y21: 0 | Z21: 0 | AA21: 0 | AB21: 0 | AC21: 0 | AD21: 0 | AE21: 0 | AF21: 0
A22: gastric decomposition time | C22: (min) | D22: 0.1 | E22: 0.1 | F22: 0.1 | G22: 5 | H22: 5 | I22: 50 | J22: 50 | K22: =emulsie!D12 -> 1 | L22: 0.1 | M22: 10 | N22: 50 | O22: 1 | P22: 10 | Q22: 100 | R22: 50 | S22: 50 | T22: 50 | U22: 50 | V22: 50 | W22: 50 | X22: 0.1 | Y22: 0.1 | Z22: 0.1 | AA22: 0.1 | AB22: 0.1 | AC22: 0.1 | AD22: 0.1 | AE22: 0.1 | AF22: 0.1
C23: decomposes into (compound) | D23: =water!D13 -> 0 | E23: =glucose!D13 -> 0 | F23: =sucrose!D13 -> 0 | G23: ='milk choc'!D13 -> 6 | H23: 7 | I23: ='gastic milk choc'!D13 -> 0 | J23: ='gastic milk choc arab'!D13 -> 0 | K23: =emulsie!D13 -> 0 | L23: =arabinose!D13 -> 0 | M23: 0 | N23: 0 | O23: 0 | P23: 10 | Q23: 11 | R23: 16 | S23: 17 | T23: 0 | U23: 19 | V23: 20 | W23: 0 | X23: 0 | Y23: 0 | Z23: 0 | AA23: 0 | AB23: 0 | AC23: 0 | AD23: 0 | AE23: 0 | AF23: 0
C24: (%) | D24: =water!D14 -> 0 | E24: =glucose!D14 -> 0 | F24: =sucrose!D14 -> 0 | G24: 100 | H24: 100 | I24: ='gastic milk choc'!D14 -> 0 | J24: ='gastic milk choc arab'!D14 -> 0 | K24: =emulsie!D14 -> 0 | L24: =arabinose!D14 -> 0 | M24: 0 | N24: 0 | O24: 0 | P24: 50 | Q24: 100 | R24: 60 | S24: 100 | T24: 0 | U24: 60 | V24: 100 | W24: 0 | X24: 0 | Y24: 0 | Z24: 0 | AA24: 0 | AB24: 0 | AC24: 0 | AD24: 0 | AE24: 0 | AF24: 0
C25: and (compound) | D25: =water!D15 -> 0 | E25: =glucose!D15 -> 0 | F25: =sucrose!D15 -> 0 | G25: ='milk choc'!D15 -> 0 | H25: ='milk chocolate arabinose'!D15 -> 0 | I25: ='gastic milk choc'!D15 -> 0 | J25: ='gastic milk choc arab'!D15 -> 0 | K25: =emulsie!D15 -> 0 | L25: =arabinose!D15 -> 0 | M25: 0 | N25: 0 | O25: 0 | P25: 0 | Q25: 0 | R25: 0 | S25: 0 | T25: 0 | U25: 20 | V25: 0 | W25: 0 | X25: 0 | Y25: 0 | Z25: 0 | AA25: 0 | AB25: 0 | AC25: 0 | AD25: 0 | AE25: 0 | AF25: 0
C26: (%) | D26: =water!D16 -> 0 | E26: =glucose!D16 -> 0 | F26: =sucrose!D16 -> 0 | G26: ='milk choc'!D16 -> 0 | H26: ='milk chocolate arabinose'!D16 -> 0 | I26: ='gastic milk choc'!D16 -> 0 | J26: ='gastic milk choc arab'!D16 -> 0 | K26: =emulsie!D16 -> 0 | L26: =arabinose!D16 -> 0 | M26: 0 | N26: 0 | O26: 0 | P26: 0 | Q26: 0 | R26: 40 | S26: 0 | T26: 0 | U26: 40 | V26: 0 | W26: 0 | X26: 0 | Y26: 0 | Z26: 0 | AA26: 0 | AB26: 0 | AC26: 0 | AD26: 0 | AE26: 0 | AF26: 0
A27: intestinal decomposition time | C27: (min) | D27: 0.1 | E27: 0.1 | F27: 0.1 | G27: 1 | H27: 1 | I27: 1 | J27: 1 | K27: =emulsie!D17 -> 1 | L27: 0.1 | M27: 2 | N27: 10 | O27: 1 | P27: 10 | Q27: 100 | R27: 10 | S27: 20 | T27: 20 | U27: 10 | V27: 20 | W27: 20 | X27: 0.1 | Y27: 0.1 | Z27: 0.1 | AA27: 0.1 | AB27: 1 | AC27: 0.1 | AD27: 0.1 | AE27: 0.1 | AF27: 1
C28: decomposes into (compound) | D28: =water!D18 -> 0 | E28: =glucose!D18 -> 0 | F28: =sucrose!D18 -> 0 | G28: 6 | H28: 7 | I28: ='gastic milk choc'!D18 -> 0 | J28: ='gastic milk choc arab'!D18 -> 0 | K28: =emulsie!D18 -> 0 | L28: =arabinose!D18 -> 0 | M28: 0 | N28: 0 | O28: 0 | P28: 10 | Q28: 11 | R28: 16 | S28: 17 | T28: 0 | U28: 19 | V28: 20 | W28: 0 | X28: 0 | Y28: 0 | Z28: 0 | AA28: 0 | AB28: 0 | AC28: 0 | AD28: 0 | AE28: 0 | AF28: 0
C29: (%) | D29: =water!D19 -> 0 | E29: =glucose!D19 -> 0 | F29: =sucrose!D19 -> 0 | G29: 100 | H29: 100 | I29: ='gastic milk choc'!D19 -> 0 | J29: ='gastic milk choc arab'!D19 -> 0 | K29: =emulsie!D19 -> 0 | L29: =arabinose!D19 -> 0 | M29: 0 | N29: 0 | O29: 0 | P29: 50 | Q29: 100 | R29: 50 | S29: 100 | T29: 0 | U29: 50 | V29: 100 | W29: 0 | X29: 0 | Y29: 0 | Z29: 0 | AA29: 0 | AB29: 0 | AC29: 0 | AD29: 0 | AE29: 0 | AF29: 0
C30: and (compound) | D30: =water!D20 -> 0 | E30: =glucose!D20 -> 0 | F30: =sucrose!D20 -> 0 | G30: ='milk choc'!D20 -> 0 | H30: ='milk chocolate arabinose'!D20 -> 0 | I30: ='gastic milk choc'!D20 -> 0 | J30: ='gastic milk choc arab'!D20 -> 0 | K30: =emulsie!D20 -> 0 | L30: =arabinose!D20 -> 0 | M30: 0 | N30: 0 | O30: 0 | P30: 0 | Q30: 0 | R30: 0 | S30: 0 | T30: 0 | U30: 20 | V30: 0 | W30: 0 | X30: 0 | Y30: 0 | Z30: 0 | AA30: 0 | AB30: 0 | AC30: 0 | AD30: 0 | AE30: 0 | AF30: 0
C31: (%) | D31: =water!D21 -> 0 | E31: =glucose!D21 -> 0 | F31: =sucrose!D21 -> 0 | G31: ='milk choc'!D21 -> 0 | H31: ='milk chocolate arabinose'!D21 -> 0 | I31: ='gastic milk choc'!D21 -> 0 | J31: ='gastic milk choc arab'!D21 -> 0 | K31: =emulsie!D21 -> 0 | L31: =arabinose!D21 -> 0 | M31: 0 | N31: 0 | O31: 0 | P31: 0 | Q31: 0 | R31: 50 | S31: 0 | T31: 0 | U31: 50 | V31: 0 | W31: 0 | X31: 0 | Y31: 0 | Z31: 0 | AA31: 0 | AB31: 0 | AC31: 0 | AD31: 0 | AE31: 0 | AF31: 0
B34: Ingredient
A35: 1 | B35: water | C35: (g) | D35: =water!D25 -> 100 | E35: =glucose!D25 -> 0 | F35: =sucrose!D25 -> 0 | G35: ='milk choc'!D25 -> 0 | H35: ='milk chocolate arabinose'!D25 -> 0 | I35: ='gastic milk choc'!D25 -> 36.94 | J35: ='gastic milk choc arab'!D25 -> 36.94 | K35: =emulsie!D25 -> 50 | L35: =arabinose!D25 -> 0 | M35: 0 | N35: 0 | O35: 0 | P35: 14 | Q35: 14 | R35: 67 | S35: 67 | T35: 67 | U35: 54 | V35: 54 | W35: 54 | X35: 100 | Y35: 100 | Z35: 100 | AA35: 100 | AB35: 0 | AC35: 0 | AD35: 0 | AE35: 0 | AF35: 113
A36: 2 | B36: fat | C36: (g) | D36: =water!D26 -> 0 | E36: =glucose!D26 -> 0 | F36: =sucrose!D26 -> 0 | G36: ='milk choc'!D26 -> 32.73 | H36: ='milk chocolate arabinose'!D26 -> 32.73 | I36: ='gastic milk choc'!D26 -> 29.13 | J36: ='gastic milk choc arab'!D26 -> 29.13 | K36: =emulsie!D26 -> 50 | L36: =arabinose!D26 -> 0 | M36: 0 | N36: 0 | O36: 0 | P36: 0 | Q36: 0 | R36: 9 | S36: 9 | T36: 9 | U36: 9 | V36: 9 | W36: 9 | X36: 0 | Y36: 0 | Z36: 0 | AA36: 0 | AB36: 0 | AC36: 0 | AD36: 0 | AE36: 0 | AF36: 0
A37: 3 | B37: glucose | C37: (g) | D37: =water!D27 -> 0 | E37: 99 | F37: =sucrose!D27 -> 0 | G37: ='milk choc'!D27 -> 0 | H37: ='milk chocolate arabinose'!D27 -> 0 | I37: ='gastic milk choc'!D27 -> 0 | J37: ='gastic milk choc arab'!D27 -> 0 | K37: =emulsie!D27 -> 0 | L37: =arabinose!D27 -> 0 | M37: 0 | N37: 0 | O37: 0 | P37: 0 | Q37: 0 | R37: 0 | S37: 0 | T37: 0 | U37: 0 | V37: 0 | W37: 0 | X37: 0 | Y37: 0 | Z37: 0 | AA37: 0 | AB37: 0 | AC37: 0 | AD37: 0 | AE37: 0 | AF37: 0
A38: 4 | B38: protein | C38: (g) | D38: =water!D28 -> 0 | E38: =glucose!D28 -> 0 | F38: =sucrose!D28 -> 0 | G38: ='milk choc'!D28 -> 1.08 | H38: ='milk chocolate arabinose'!D28 -> 1.08 | I38: ='gastic milk choc'!D28 -> 1.08 | J38: ='gastic milk choc arab'!D28 -> 1.08 | K38: =emulsie!D28 -> 0 | L38: =arabinose!D28 -> 0 | M38: 0 | N38: 0 | O38: 0 | P38: 0 | Q38: 0 | R38: 6 | S38: 6 | T38: 6 | U38: 6 | V38: 6 | W38: 6 | X38: 0 | Y38: 0 | Z38: 0 | AA38: 0 | AB38: 0 | AC38: 0 | AD38: 0 | AE38: 0 | AF38: 6
A39: 5 | B39: pharm | C39: (g) | D39: =water!D29 -> 0 | E39: =glucose!D29 -> 0 | F39: =sucrose!D29 -> 0 | G39: ='milk choc'!D29 -> 0 | H39: ='milk chocolate arabinose'!D29 -> 0 | I39: ='gastic milk choc'!D29 -> 0 | J39: ='gastic milk choc arab'!D29 -> 0 | K39: =emulsie!D29 -> 0 | L39: =arabinose!D29 -> 0 | M39: 0 | N39: 0 | O39: 0 | P39: 0 | Q39: 0 | R39: 0 | S39: 0 | T39: 0 | U39: 0 | V39: 0 | W39: 0 | X39: 0 | Y39: 0 | Z39: 0 | AA39: 0 | AB39: 0 | AC39: 0 | AD39: 0 | AE39: 0 | AF39: 0
A40: 6 | B40: pharm inactive | C40: (g) | D40: =water!D30 -> 0 | E40: =glucose!D30 -> 0 | F40: =sucrose!D30 -> 0 | G40: ='milk choc'!D30 -> 0 | H40: ='milk chocolate arabinose'!D30 -> 0 | I40: ='gastic milk choc'!D30 -> 0 | J40: ='gastic milk choc arab'!D30 -> 0 | K40: =emulsie!D30 -> 0 | L40: =arabinose!D30 -> 0 | M40: 0 | N40: 0 | O40: 0 | P40: 0 | Q40: 0 | R40: 0 | S40: 0 | T40: 0 | U40: 0 | V40: 0 | W40: 0 | X40: 0 | Y40: 0 | Z40: 0 | AA40: 0 | AB40: 0 | AC40: 0 | AD40: 0 | AE40: 0 | AF40: 0
A41: 10 | B41: RDS | C41: (g) | D41: =water!D31 -> 0 | E41: =glucose!D31 -> 0 | F41: =sucrose!D31 -> 0 | G41: ='milk choc'!D31 -> 0 | H41: ='milk chocolate arabinose'!D31 -> 0 | I41: ='gastic milk choc'!D31 -> 0 | J41: ='gastic milk choc arab'!D31 -> 0 | K41: =emulsie!D31 -> 0 | L41: =arabinose!D31 -> 0 | M41: 99 | N41: 0 | O41: 0 | P41: 75 | Q41: 0 | R41: 50 | S41: 50 | T41: 50 | U41: 50 | V41: 50 | W41: 50 | X41: 0 | Y41: 0 | Z41: 0 | AA41: 0 | AB41: 0 | AC41: 0 | AD41: 0 | AE41: 0 | AF41: 0
A42: 11 | B42: SDS | C42: (g) | D42: =water!D32 -> 0 | E42: =glucose!D32 -> 0 | F42: =sucrose!D32 -> 0 | G42: ='milk choc'!D32 -> 0 | H42: ='milk chocolate arabinose'!D32 -> 0 | I42: ='gastic milk choc'!D32 -> 0 | J42: ='gastic milk choc arab'!D32 -> 0 | K42: =emulsie!D32 -> 0 | L42: =arabinose!D32 -> 0 | M42: 0 | N42: 99 | O42: 0 | P42: 0 | Q42: 75 | R42: 0 | S42: 0 | T42: 0 | U42: 0 | V42: 0 | W42: 0 | X42: 0 | Y42: 0 | Z42: 0 | AA42: 0 | AB42: 0 | AC42: 0 | AD42: 0 | AE42: 0 | AF42: 0
A43: 12 | B43: RS | C43: (g) | D43: =water!D33 -> 0 | E43: =glucose!D33 -> 0 | F43: =sucrose!D33 -> 0 | G43: ='milk choc'!D33 -> 6 | H43: ='milk chocolate arabinose'!D33 -> 6 | I43: ='gastic milk choc'!D33 -> 1.78 | J43: ='gastic milk choc arab'!D33 -> 1.78 | K43: =emulsie!D33 -> 0 | L43: =arabinose!D33 -> 0 | M43: 0 | N43: 0 | O43: 99 | P43: 0 | Q43: 0 | R43: 0 | S43: 0 | T43: 0 | U43: 0 | V43: 0 | W43: 0 | X43: 0 | Y43: 0 | Z43: 0 | AA43: 0 | AB43: 0 | AC43: 0 | AD43: 0 | AE43: 0 | AF43: 0
A44: 20 | B44: FA | C44: (g) | D44: =water!D34 -> 0 | E44: =glucose!D34 -> 0 | F44: =sucrose!D34 -> 0 | G44: ='milk choc'!D34 -> 0 | H44: ='milk chocolate arabinose'!D34 -> 0 | I44: ='gastic milk choc'!D34 -> 0 | J44: ='gastic milk choc arab'!D34 -> 0 | K44: =emulsie!D34 -> 0 | L44: =arabinose!D34 -> 0 | M44: 0 | N44: 0 | O44: 0 | P44: 0 | Q44: 0 | R44: 0 | S44: 0 | T44: 0 | U44: 0 | V44: 0 | W44: 0 | X44: 0 | Y44: 0 | Z44: 0 | AA44: 0 | AB44: 0 | AC44: 0 | AD44: 0 | AE44: 0 | AF44: 0
...

Sheet water
B1: Water
B3: Compound quantifiers | C3: units | D3: water
B4: pH | C4: (-) | D4: 7
B5: solid | C5: (0/1) | D5: 0
B6: viscosity | C6: (mPa.s) | D6: 1
B7: oral decomposition time | C7: (min) | D7: 1
B8: decomposes into | C8: (compound number) | D8: 0
C9: (%) | D9: 0
B10: and | C10: ( compound number) | D10: 0
C11: (%) | D11: 0
B12: gastric decomposition time | C12: (min) | D12: 1
B13: decomposes into | C13: (compound number) | D13: 0
C14: (%) | D14: 0
B15: and | C15: (compound number) | D15: 0
C16: (%) | D16: 0
B17: intestinal composition time | C17: (min) | D17: 1
B18: decomposes into | C18: (compound number) | D18: 0
C19: (%) | D19: 0
B20: and | C20: (compound number) | D20: 0
C21: (%) | D21: 0
B24: INGREDIENTS
A25: 1 | B25: water | C25: gram % | D25: 100
A26: 2 | B26: fat | C26: =$C$25 -> gram % | D26: 0
A27: 3 | B27: glucose | C27: =$C$25 -> gram % | D27: 0
A28: 4 | B28: protein | C28: =$C$25 -> gram % | D28: 0
A29: 5 | B29: pharm | C29: =$C$25 -> gram % | D29: 0
A30: 6 | B30: pharm inactive | C30: =$C$25 -> gram % | D30: 0
A31: 10 | B31: RDS | C31: =$C$25 -> gram % | D31: 0
A32: 11 | B32: SDS | C32: =$C$25 -> gram % | D32: 0
A33: 12 | B33: RS | C33: =$C$25 -> gram % | D33: 0
A34: 20 | B34: FA | C34: =$C$25 -> gram % | D34: 0
A35: 21 | B35: sucrose | C35: =$C$25 -> gram % | D35: 0
A36: 22 | B36: fructose | C36: =$C$25 -> gram % | D36: 0
A37: 23 | B37: maltose | C37: =$C$25 -> gram % | D37: 0
... A63: 79 | B63: HCO3- | C63: =$C$25 -> gram % | D63: 0
A64: 80 | B64: H+ ions | C64: mol/100g | D64: 0
B66: density | C66: g/ml | D66: 1

Sheet glucose
B1: Glucose
B3: Component quantifiers | C3: units | D3: glucose
B4: pH | C4: (-) | D4: 7
B5: solid | C5: (0/1) | D5: 1
B6: viscosity | C6: (mPa.s) | D6: 1
B7: oral decomposition time | C7: (min) | D7: 1
B8: decomposes into | C8: (compound number) | D8: 0
C9: (%) | D9: 0
B10: and | C10: ( compound number) | D10: 0
C11: (%) | D11: 0
B12: gastric decomposition time | C12: (min) | D12: 1
B13: decomposes into | C13: (compound number) | D13: 0
C14: (%) | D14: 0
B15: and | C15: (compound number) | D15: 0
C16: (%) | D16: 0
B17: intestinal composition time | C17: (min) | D17: 1
B18: decomposes into | C18: (compound number) | D18: 0
C19: (%) | D19: 0
B20: and | C20: (compound number) | D20: 0
C21: (%) | D21: 0
B24: INGREDIENTS
A25: 1 | B25: water | C25: gram % | D25: 0
A26: 2 | B26: fat | C26: =$C$25 -> gram % | D26: 0
A27: 3 | B27: glucose | C27: =$C$25 -> gram % | D27: 100
A28: 4 | B28: protein | C28: =$C$25 -> gram % | D28: 0
A29: 5 | B29: pharm | C29: =$C$25 -> gram % | D29: 0
A30: 6 | B30: pharm inactive | C30: =$C$25 -> gram % | D30: 0
A31: 10 | B31: RDS | C31: =$C$25 -> gram % | D31: 0
A32: 11 | B32: SDS | C32: =$C$25 -> gram % | D32: 0
A33: 12 | B33: RS | C33: =$C$25 -> gram % | D33: 0
A34: 20 | B34: FA | C34: =$C$25 -> gram % | D34: 0
A35: 21 | B35: sucrose | C35: =$C$25 -> gram % | D35: 0
A36: 22 | B36: fructose | C36: =$C$25 -> gram % | D36: 0
A37: 23 | B37: maltose | C37: =$C$25 -> gram % | D37: 0
... A63: 79 | B63: HCO3- | C63: =$C$25 -> gram % | D63: 0
A64: 80 | B64: H+ ions | C64: mol/100g | D64: 0
B66: density | C66: g/ml | D66: 1.44

Sheet sucrose
B1: Sucrose
B3: Component quantifiers | C3: units | D3: sucrose
B4: pH | C4: (-) | D4: 7
B5: solid | C5: (0/1) | D5: 1
B6: viscosity | C6: (mPa.s) | D6: 1
B7: oral decomposition time | C7: (min) | D7: 1
B8: decomposes into | C8: (compound number) | D8: 0
C9: (%) | D9: 0
B10: and | C10: ( compound number) | D10: 0
C11: (%) | D11: 0
B12: gastric decomposition time | C12: (min) | D12: 1
B13: decomposes into | C13: (compound number) | D13: 0
C14: (%) | D14: 0
B15: and | C15: (compound number) | D15: 0
C16: (%) | D16: 0
B17: intestinal composition time | C17: (min) | D17: 1
B18: decomposes into | C18: (compound number) | D18: 0
C19: (%) | D19: 0
B20: and | C20: (compound number) | D20: 0
C21: (%) | D21: 0
B24: INGREDIENTS
A25: 1 | B25: water | C25: gram % | D25: 0
A26: 2 | B26: fat | C26: =$C$25 -> gram % | D26: 0
A27: 3 | B27: glucose | C27: =$C$25 -> gram % | D27: 0
A28: 4 | B28: protein | C28: =$C$25 -> gram % | D28: 0
A29: 5 | B29: pharm | C29: =$C$25 -> gram % | D29: 0
A30: 6 | B30: pharm inactive | C30: =$C$25 -> gram % | D30: 0
A31: 10 | B31: RDS | C31: =$C$25 -> gram % | D31: 0
A32: 11 | B32: SDS | C32: =$C$25 -> gram % | D32: 0
A33: 12 | B33: RS | C33: =$C$25 -> gram % | D33: 0
A34: 20 | B34: FA | C34: =$C$25 -> gram % | D34: 0
A35: 21 | B35: sucrose | C35: =$C$25 -> gram % | D35: 100
A36: 22 | B36: fructose | C36: =$C$25 -> gram % | D36: 0
A37: 23 | B37: maltose | C37: =$C$25 -> gram % | D37: 0
... A63: 79 | B63: HCO3- | C63: =$C$25 -> gram % | D63: 0
A64: 80 | B64: H+ ions | C64: mol/100g | D64: 0
B66: density | C66: g/ml | D66: 1.44

Sheet milk choc
B1: Milk Chocolate
B3: Component quantifiers | C3: units | D3: milk choc
B4: pH | C4: (-) | D4: 7
B5: solid | C5: (0/1) | D5: 1
B6: viscosity | C6: (mPa.s) | D6: 1
B7: oral decomposition time | C7: (min) | D7: 2
B8: decomposes into | C8: (compound number) | D8: 6
C9: (%) | D9: 100
B10: and | C10: ( compound number) | D10: 0
C11: (%) | D11: 0
B12: gastric decomposition time | C12: (min) | D12: 5
B13: decomposes into | C13: (compound number) | D13: 6
C14: (%) | D14: 100
B15: and | C15: (compound number) | D15: 0
C16: (%) | D16: 0
B17: intestinal composition time | C17: (min) | D17: 1
B18: decomposes into | C18: (compound number) | D18: 0
C19: (%) | D19: 0
B20: and | C20: (compound number) | D20: 0
C21: (%) | D21: 0
B24: INGREDIENTS
A25: 1 | B25: water | C25: gram % | D25: 0
A26: 2 | B26: fat | C26: =$C$25 -> gram % | D26: 32.73
A27: 3 | B27: glucose | C27: =$C$25 -> gram % | D27: 0
A28: 4 | B28: protein | C28: =$C$25 -> gram % | D28: 1.08
A29: 5 | B29: pharm | C29: =$C$25 -> gram % | D29: 0
A30: 6 | B30: pharm inactive | C30: =$C$25 -> gram % | D30: 0
A31: 10 | B31: RDS | C31: =$C$25 -> gram % | D31: 0
A32: 11 | B32: SDS | C32: =$C$25 -> gram % | D32: 0
A33: 12 | B33: RS | C33: =$C$25 -> gram % | D33: 6
A34: 20 | B34: FA | C34: =$C$25 -> gram % | D34: 0
A35: 21 | B35: sucrose | C35: =$C$25 -> gram % | D35: 41.5
A36: 22 | B36: fructose | C36: =$C$25 -> gram % | D36: 0
A37: 23 | B37: maltose | C37: =$C$25 -> gram % | D37: 0
... A63: 79 | B63: HCO3- | C63: =$C$25 -> gram % | D63: 0
A64: 80 | B64: H+ ions | C64: mol/100g | D64: 0
D65: =SUM(D25:D64) -> 100.31
B66: density | C66: g/ml | D66: 1.3

Sheet milk chocolate arabinose
B1: Milk Chocolate arabinose
B3: Component quantifiers | C3: units | D3: milk choc arab
B4: pH | C4: (-) | D4: 7
B5: solid | C5: (0/1) | D5: 1
B6: viscosity | C6: (mPa.s) | D6: 1
B7: oral decomposition time | C7: (min) | D7: 2
B8: decomposes into | C8: (compound number) | D8: 6
C9: (%) | D9: 50
B10: and | C10: ( compound number) | D10: 0
C11: (%) | D11: 0
B12: gastric decomposition time | C12: (min) | D12: 5
B13: decomposes into | C13: (compound number) | D13: 6
C14: (%) | D14: 0
B15: and | C15: (compound number) | D15: 0
C16: (%) | D16: 0
B17: intestinal composition time | C17: (min) | D17: 1
B18: decomposes into | C18: (compound number) | D18: 0
C19: (%) | D19: 0
B20: and | C20: (compound number) | D20: 0
C21: (%) | D21: 0
B24: INGREDIENTS
A25: 1 | B25: water | C25: gram % | D25: 0
A26: 2 | B26: fat | C26: =$C$25 -> gram % | D26: 32.73
A27: 3 | B27: glucose | C27: =$C$25 -> gram % | D27: 0
A28: 4 | B28: protein | C28: =$C$25 -> gram % | D28: 1.08
A29: 5 | B29: pharm | C29: =$C$25 -> gram % | D29: 0
A30: 6 | B30: pharm inactive | C30: =$C$25 -> gram % | D30: 0
A31: 10 | B31: RDS | C31: =$C$25 -> gram % | D31: 0
A32: 11 | B32: SDS | C32: =$C$25 -> gram % | D32: 0
A33: 12 | B33: RS | C33: =$C$25 -> gram % | D33: 6
A34: 20 | B34: FA | C34: =$C$25 -> gram % | D34: 0
A35: 21 | B35: sucrose | C35: =$C$25 -> gram % | D35: 29.7
A36: 22 | B36: fructose | C36: =$C$25 -> gram % | D36: 0
A37: 23 | B37: maltose | C37: =$C$25 -> gram % | D37: 0
... A63: 79 | B63: HCO3- | C63: =$C$25 -> gram % | D63: 0
A64: 80 | B64: H+ ions | C64: mol/100g | D64: 0
D65: =SUM(D25:D64) -> 100.41
B66: density | C66: g/ml | D66: 1.3

Sheet gastic milk choc
B1: Gastic Milk Chocolate
B3: Component quantifiers | C3: units | D3: milk choc
B4: pH | C4: (-) | D4: 7
B5: solid | C5: (0/1) | D5: 1
B6: viscosity | C6: (mPa.s) | D6: 1
B7: oral decomposition time | C7: (min) | D7: 1
B8: decomposes into | C8: (compound number) | D8: 0
C9: (%) | D9: 0
B10: and | C10: ( compound number) | D10: 0
C11: (%) | D11: 0
B12: gastric decomposition time | C12: (min) | D12: 20
B13: decomposes into | C13: (compound number) | D13: 0
C14: (%) | D14: 0
B15: and | C15: (compound number) | D15: 0
C16: (%) | D16: 0
B17: intestinal composition time | C17: (min) | D17: 1
B18: decomposes into | C18: (compound number) | D18: 0
C19: (%) | D19: 0
B20: and | C20: (compound number) | D20: 0
C21: (%) | D21: 0
B24: INGREDIENTS
A25: 1 | B25: water | C25: gram % | D25: 36.94
A26: 2 | B26: fat | C26: =$C$25 -> gram % | D26: 29.13
A27: 3 | B27: glucose | C27: =$C$25 -> gram % | D27: 0
A28: 4 | B28: protein | C28: =$C$25 -> gram % | D28: 1.08
A29: 5 | B29: pharm | C29: =$C$25 -> gram % | D29: 0
A30: 6 | B30: pharm inactive | C30: =$C$25 -> gram % | D30: 0
A31: 10 | B31: RDS | C31: =$C$25 -> gram % | D31: 0
A32: 11 | B32: SDS | C32: =$C$25 -> gram % | D32: 0
A33: 12 | B33: RS | C33: =$C$25 -> gram % | D33: 1.78
A34: 20 | B34: FA | C34: =$C$25 -> gram % | D34: 0
A35: 21 | B35: sucrose | C35: =$C$25 -> gram % | D35: 20
A36: 22 | B36: fructose | C36: =$C$25 -> gram % | D36: 0
A37: 23 | B37: maltose | C37: =$C$25 -> gram % | D37: 0
... A63: 79 | B63: HCO3- | C63: =$C$25 -> gram % | D63: 0
A64: 80 | B64: H+ ions | C64: mol/100g | D64: 0
D65: =SUM(D25:D64) -> 99.83
B66: density | C66: g/ml | D66: 1.2

Sheet gastic milk choc arab
B1: Gastic Milk Chocolate
B3: Component quantifiers | C3: units | D3: milk choc
B4: pH | C4: (-) | D4: 7
B5: solid | C5: (0/1) | D5: 1
B6: viscosity | C6: (mPa.s) | D6: 1
B7: oral decomposition time | C7: (min) | D7: 1
B8: decomposes into | C8: (compound number) | D8: 0
C9: (%) | D9: 0
B10: and | C10: ( compound number) | D10: 0
C11: (%) | D11: 0
B12: gastric decomposition time | C12: (min) | D12: 20
B13: decomposes into | C13: (compound number) | D13: 0
C14: (%) | D14: 0
B15: and | C15: (compound number) | D15: 0
C16: (%) | D16: 0
B17: intestinal composition time | C17: (min) | D17: 1
B18: decomposes into | C18: (compound number) | D18: 0
C19: (%) | D19: 0
B20: and | C20: (compound number) | D20: 0
C21: (%) | D21: 0
B24: INGREDIENTS
A25: 1 | B25: water | C25: gram % | D25: 36.94
A26: 2 | B26: fat | C26: =$C$25 -> gram % | D26: 29.13
A27: 3 | B27: glucose | C27: =$C$25 -> gram % | D27: 0
A28: 4 | B28: protein | C28: =$C$25 -> gram % | D28: 1.08
A29: 5 | B29: pharm | C29: =$C$25 -> gram % | D29: 0
A30: 6 | B30: pharm inactive | C30: =$C$25 -> gram % | D30: 0
A31: 10 | B31: RDS | C31: =$C$25 -> gram % | D31: 0
A32: 11 | B32: SDS | C32: =$C$25 -> gram % | D32: 0
A33: 12 | B33: RS | C33: =$C$25 -> gram % | D33: 1.78
A34: 20 | B34: FA | C34: =$C$25 -> gram % | D34: 0
A35: 21 | B35: sucrose | C35: =$C$25 -> gram % | D35: 15
A36: 22 | B36: fructose | C36: =$C$25 -> gram % | D36: 0
A37: 23 | B37: maltose | C37: =$C$25 -> gram % | D37: 0
... A63: 79 | B63: HCO3- | C63: =$C$25 -> gram % | D63: 0
A64: 80 | B64: H+ ions | C64: mol/100g | D64: 0
D65: =SUM(D25:D64) -> 99.83
B66: density | C66: g/ml | D66: 1.2

Sheet emulsie
B1: Emulsie
B3: Compound quantifiers | C3: units | D3: water
B4: pH | C4: (-) | D4: 7
B5: solid | C5: (0/1) | D5: 0
B6: viscosity | C6: (mPa.s) | D6: 1
B7: oral decomposition time | C7: (min) | D7: 1
B8: decomposes into | C8: (compound number) | D8: 0
C9: (%) | D9: 0
B10: and | C10: ( compound number) | D10: 0
C11: (%) | D11: 0
B12: gastric decomposition time | C12: (min) | D12: 1
B13: decomposes into | C13: (compound number) | D13: 0
C14: (%) | D14: 0
B15: and | C15: (compound number) | D15: 0
C16: (%) | D16: 0
B17: intestinal composition time | C17: (min) | D17: 1
B18: decomposes into | C18: (compound number) | D18: 0
C19: (%) | D19: 0
B20: and | C20: (compound number) | D20: 0
C21: (%) | D21: 0
B24: INGREDIENTS
A25: 1 | B25: water | C25: gram % | D25: 50
A26: 2 | B26: fat | C26: =$C$25 -> gram % | D26: 50
A27: 3 | B27: glucose | C27: =$C$25 -> gram % | D27: 0
A28: 4 | B28: protein | C28: =$C$25 -> gram % | D28: 0
A29: 5 | B29: pharm | C29: =$C$25 -> gram % | D29: 0
A30: 6 | B30: pharm inactive | C30: =$C$25 -> gram % | D30: 0
A31: 10 | B31: RDS | C31: =$C$25 -> gram % | D31: 0
A32: 11 | B32: SDS | C32: =$C$25 -> gram % | D32: 0
A33: 12 | B33: RS | C33: =$C$25 -> gram % | D33: 0
A34: 20 | B34: FA | C34: =$C$25 -> gram % | D34: 0
A35: 21 | B35: sucrose | C35: =$C$25 -> gram % | D35: 0
A36: 22 | B36: fructose | C36: =$C$25 -> gram % | D36: 0
A37: 23 | B37: maltose | C37: =$C$25 -> gram % | D37: 0
... A63: 79 | B63: HCO3- | C63: =$C$25 -> gram % | D63: 0
A64: 80 | B64: H+ ions | C64: mol/100g | D64: 0
D65: =SUM(D25:D64) -> 100
B66: density | C66: g/ml | D66: 0.95

Sheet arabinose
B1: Arabinose
B3: Component quantifiers | C3: units | D3: sucrose
B4: pH | C4: (-) | D4: 7
B5: solid | C5: (0/1) | D5: 1
B6: viscosity | C6: (mPa.s) | D6: 1
B7: oral decomposition time | C7: (min) | D7: 1
B8: decomposes into | C8: (compound number) | D8: 0
C9: (%) | D9: 0
B10: and | C10: ( compound number) | D10: 0
C11: (%) | D11: 0
B12: gastric decomposition time | C12: (min) | D12: 1
B13: decomposes into | C13: (compound number) | D13: 0
C14: (%) | D14: 0
B15: and | C15: (compound number) | D15: 0
C16: (%) | D16: 0
B17: intestinal composition time | C17: (min) | D17: 1
B18: decomposes into | C18: (compound number) | D18: 0
C19: (%) | D19: 0
B20: and | C20: (compound number) | D20: 0
C21: (%) | D21: 0
B24: INGREDIENTS
A25: 1 | B25: water | C25: gram % | D25: 0
A26: 2 | B26: fat | C26: =$C$25 -> gram % | D26: 0
A27: 3 | B27: glucose | C27: =$C$25 -> gram % | D27: 0
A28: 4 | B28: protein | C28: =$C$25 -> gram % | D28: 0
A29: 5 | B29: pharm | C29: =$C$25 -> gram % | D29: 0
A30: 6 | B30: pharm inactive | C30: =$C$25 -> gram % | D30: 0
A31: 10 | B31: RDS | C31: =$C$25 -> gram % | D31: 0
A32: 11 | B32: SDS | C32: =$C$25 -> gram % | D32: 0
A33: 12 | B33: RS | C33: =$C$25 -> gram % | D33: 0
A34: 20 | B34: FA | C34: =$C$25 -> gram % | D34: 0
A35: 21 | B35: sucrose | C35: =$C$25 -> gram % | D35: 0
A36: 22 | B36: fructose | C36: =$C$25 -> gram % | D36: 0
A37: 23 | B37: maltose | C37: =$C$25 -> gram % | D37: 0
... A63: 79 | B63: HCO3- | C63: =$C$25 -> gram % | D63: 0
A64: 80 | B64: H+ ions | C64: mol/100g | D64: 0
B66: density | C66: g/ml | D66: 1.44

Sheet rapid starch
B1: Rapid starch
B3: Component quantifiers | C3: units | D3: Rapid starch
B4: pH | C4: (-) | D4: 7
B5: solid | C5: (0/1) | D5: 0
B6: viscosity | C6: (mPa.s) | D6: 1000
B7: oral decomposition time | C7: (min) | D7: 1
B8: decomposes into | C8: (compound number) | D8: 0
C9: (%) | D9: 0
B10: and | C10: ( compound number) | D10: 0
C11: (%) | D11: 0
B12: gastric decomposition time | C12: (min) | D12: 1
B13: decomposes into | C13: (compound number) | D13: 0
C14: (%) | D14: 0
B15: and | C15: (compound number) | D15: 0
C16: (%) | D16: 0
B17: intestinal composition time | C17: (min) | D17: 1
B18: decomposes into | C18: (compound number) | D18: 0
C19: (%) | D19: 0
B20: and | C20: (compound number) | D20: 0
C21: (%) | D21: 0
B24: INGREDIENTS
A25: 1 | B25: water | C25: gram % | D25: 0
A26: 2 | B26: fat | C26: =$C$25 -> gram % | D26: 0
A27: 3 | B27: glucose | C27: =$C$25 -> gram % | D27: 0
A28: 4 | B28: protein | C28: =$C$25 -> gram % | D28: 0
A29: 5 | B29: pharm | C29: =$C$25 -> gram % | D29: 0
A30: 6 | B30: pharm inactive | C30: =$C$25 -> gram % | D30: 0
A31: 10 | B31: RDS | C31: =$C$25 -> gram % | D31: 100
A32: 11 | B32: SDS | C32: =$C$25 -> gram % | D32: 0
A33: 12 | B33: RS | C33: =$C$25 -> gram % | D33: 0
A34: 20 | B34: FA | C34: =$C$25 -> gram % | D34: 0
A35: 21 | B35: sucrose | C35: =$C$25 -> gram % | D35: 0
A36: 22 | B36: fructose | C36: =$C$25 -> gram % | D36: 0
A37: 23 | B37: maltose | C37: =$C$25 -> gram % | D37: 0
... A63: 79 | B63: HCO3- | C63: =$C$25 -> gram % | D63: 0
A64: 80 | B64: H+ ions | C64: mol/100g | D64: 0
B66: density | C66: g/ml | D66: 1.44

Sheet slow starch
B1: Slow starch
B3: Component quantifiers | C3: units | D3: Slow starch
B4: pH | C4: (-) | D4: 7
B5: solid | C5: (0/1) | D5: 1
B6: viscosity | C6: (mPa.s) | D6: 1000
B7: oral decomposition time | C7: (min) | D7: 10
B8: decomposes into | C8: (compound number) | D8: 0
C9: (%) | D9: 0
B10: and | C10: ( compound number) | D10: 0
C11: (%) | D11: 0
B12: gastric decomposition time | C12: (min) | D12: 10
B13: decomposes into | C13: (compound number) | D13: 0
C14: (%) | D14: 0
B15: and | C15: (compound number) | D15: 0
C16: (%) | D16: 0
B17: intestinal composition time | C17: (min) | D17: 1
B18: decomposes into | C18: (compound number) | D18: 0
C19: (%) | D19: 0
B20: and | C20: (compound number) | D20: 0
C21: (%) | D21: 0
B24: INGREDIENTS
A25: 1 | B25: water | C25: gram % | D25: 0
A26: 2 | B26: fat | C26: =$C$25 -> gram % | D26: 0
A27: 3 | B27: glucose | C27: =$C$25 -> gram % | D27: 0
A28: 4 | B28: protein | C28: =$C$25 -> gram % | D28: 0
A29: 5 | B29: pharm | C29: =$C$25 -> gram % | D29: 0
A30: 6 | B30: pharm inactive | C30: =$C$25 -> gram % | D30: 0
A31: 10 | B31: RDS | C31: =$C$25 -> gram % | D31: 0
A32: 11 | B32: SDS | C32: =$C$25 -> gram % | D32: 100
A33: 12 | B33: RS | C33: =$C$25 -> gram % | D33: 0
A34: 20 | B34: FA | C34: =$C$25 -> gram % | D34: 0
A35: 21 | B35: sucrose | C35: =$C$25 -> gram % | D35: 0
A36: 22 | B36: fructose | C36: =$C$25 -> gram % | D36: 0
A37: 23 | B37: maltose | C37: =$C$25 -> gram % | D37: 0
... A63: 79 | B63: HCO3- | C63: =$C$25 -> gram % | D63: 0
A64: 80 | B64: H+ ions | C64: mol/100g | D64: 0
B66: density | C66: g/ml | D66: 1.44

Sheet resistant starch
B1: Resistant starch
B3: Component quantifiers | C3: units | D3: resistant starch
B4: pH | C4: (-) | D4: 7
B5: solid | C5: (0/1) | D5: 1
B6: viscosity | C6: (mPa.s) | D6: 10
B7: oral decomposition time | C7: (min) | D7: 1
B8: decomposes into | C8: (compound number) | D8: 0
C9: (%) | D9: 0
B10: and | C10: ( compound number) | D10: 0
C11: (%) | D11: 0
B12: gastric decomposition time | C12: (min) | D12: 1
B13: decomposes into | C13: (compound number) | D13: 0
C14: (%) | D14: 0
B15: and | C15: (compound number) | D15: 0
C16: (%) | D16: 0
B17: intestinal composition time | C17: (min) | D17: 1
B18: decomposes into | C18: (compound number) | D18: 0
C19: (%) | D19: 0
B20: and | C20: (compound number) | D20: 0
C21: (%) | D21: 0
B24: INGREDIENTS
A25: 1 | B25: water | C25: gram % | D25: 0
A26: 2 | B26: fat | C26: =$C$25 -> gram % | D26: 0
A27: 3 | B27: glucose | C27: =$C$25 -> gram % | D27: 0
A28: 4 | B28: protein | C28: =$C$25 -> gram % | D28: 0
A29: 5 | B29: pharm | C29: =$C$25 -> gram % | D29: 0
A30: 6 | B30: pharm inactive | C30: =$C$25 -> gram % | D30: 0
A31: 10 | B31: RDS | C31: =$C$25 -> gram % | D31: 0
A32: 11 | B32: SDS | C32: =$C$25 -> gram % | D32: 0
A33: 12 | B33: RS | C33: =$C$25 -> gram % | D33: 100
A34: 20 | B34: FA | C34: =$C$25 -> gram % | D34: 0
A35: 21 | B35: sucrose | C35: =$C$25 -> gram % | D35: 0
A36: 22 | B36: fructose | C36: =$C$25 -> gram % | D36: 0
A37: 23 | B37: maltose | C37: =$C$25 -> gram % | D37: 0
... A63: 79 | B63: HCO3- | C63: =$C$25 -> gram % | D63: 0
A64: 80 | B64: H+ ions | C64: mol/100g | D64: 0
B66: density | C66: g/ml | D66: 1.44
